Workbook

Sheet Forecast Work Area
A1: FORECAST WORK AREA · real $mm · t = −3…0 actuals, 1…N forecast
A2: Historicals draw from _Actuals (formulas). Blue defaults carry the prior value forward — overwrite at will. Nothing in the grey/shaded areas is hard-coded. | B2: Forecast mode ▸ | C2: Equity | D2: Payout ratio (equity) ▸ | E2: 0.365
B3: Financing mode ▸ | C3: Target FLEV | D3: Target FLEV ▸ | E3: 1.0615
A4: Period t (0 = last actual) | C4: -3 | D4: -2 | E4: -1 | F4: 0 | G4: 1 | H4: 2 | I4: 3 | J4: 4 | K4: 5 | L4: 6 | M4: 7 | N4: 8 | O4: 9 | P4: 10 | Q4: 11 | R4: 12 | S4: 13 | T4: 14 | U4: 15 | V4: 16 | W4: 17 | X4: 18 | Y4: 19 | Z4: 20 | AA4: 21 | AB4: 22 | AC4: 23 | AD4: 24 | AE4: 25 | AF4: 26 | AG4: 27 | AH4: 28 | AI4: 29 | AJ4: 30
A5: INCOME STATEMENT — build to EPS
A6: Revenue | C6: =_Actuals!C6 | D6: =_Actuals!D6 | E6: =_Actuals!E6 | F6: =_Actuals!F6 | G6: =F6*(1+G7) | H6: =G6*(1+H7) | I6: =H6*(1+I7) | J6: =I6*(1+J7) | K6: =J6*(1+K7) | L6: =K6*(1+L7) | M6: =L6*(1+M7) | N6: =M6*(1+N7) | ... AJ6: =AI6*(1+AJ7)
A7: revenue growth | D7: =IF(C6=0,"",D6/C6-1) | E7: =IF(D6=0,"",E6/D6-1) | F7: =IF(E6=0,"",F6/E6-1) | G7: =F7 | H7: =G7 | I7: =H7 | J7: =I7 | K7: =J7 | L7: =K7 | M7: =L7 | N7: =M7 | ... AJ7: =AI7
A8: Cost of goods sold (COGS) | C8: =_Actuals!C8 | D8: =_Actuals!D8 | E8: =_Actuals!E8 | F8: =_Actuals!F8 | G8: =G6-G9 | H8: =H6-H9 | I8: =I6-I9 | J8: =J6-J9 | K8: =K6-K9 | L8: =L6-L9 | M8: =M6-M9 | N8: =N6-N9 | ... AJ8: =AJ6-AJ9
A9: Gross profit | C9: =_Actuals!C9 | D9: =_Actuals!D9 | E9: =_Actuals!E9 | F9: =_Actuals!F9 | G9: =G6*G10 | H9: =H6*H10 | I9: =I6*I10 | J9: =J6*J10 | K9: =K6*K10 | L9: =L6*L10 | M9: =M6*M10 | N9: =N6*N10 | ... AJ9: =AJ6*AJ10
A10: gross margin | C10: =IF(C6=0,"",C9/C6) | D10: =IF(D6=0,"",D9/D6) | E10: =IF(E6=0,"",E9/E6) | F10: =IF(F6=0,"",F9/F6) | G10: =F10 | H10: =G10 | I10: =H10 | J10: =I10 | K10: =J10 | L10: =K10 | M10: =L10 | N10: =M10 | ... AJ10: =AI10
A11: Selling, general & admin (SG&A) | C11: =_Actuals!C11 | D11: =_Actuals!D11 | E11: =_Actuals!E11 | F11: =_Actuals!F11 | G11: =G6*G12 | H11: =H6*H12 | I11: =I6*I12 | J11: =J6*J12 | K11: =K6*K12 | L11: =L6*L12 | M11: =M6*M12 | N11: =N6*N12 | ... AJ11: =AJ6*AJ12
A12: SG&A % of revenue | C12: =IF(C6=0,"",C11/C6) | D12: =IF(D6=0,"",D11/D6) | E12: =IF(E6=0,"",E11/E6) | F12: =IF(F6=0,"",F11/F6) | G12: =F12 | H12: =G12 | I12: =H12 | J12: =I12 | K12: =J12 | L12: =K12 | M12: =L12 | N12: =M12 | ... AJ12: =AI12
A13: Depreciation & amortization (D&A) | C13: =_Actuals!C13 | D13: =_Actuals!D13 | E13: =_Actuals!E13 | F13: =_Actuals!F13 | G13: =G14*F49 | H13: =H14*G49 | I13: =I14*H49 | J13: =J14*I49 | K13: =K14*J49 | L13: =L14*K49 | M13: =M14*L49 | N13: =N14*M49 | ... AJ13: =AJ14*AI49
A14: depreciation rate (on prior net PP&E) | D14: =IF(C49=0,"",D13/C49) | E14: =IF(D49=0,"",E13/D49) | F14: =IF(E49=0,"",F13/E49) | G14: =F14 | H14: =G14 | I14: =H14 | J14: =I14 | K14: =J14 | L14: =K14 | M14: =L14 | N14: =M14 | ... AJ14: =AI14
A15: Operating income (EBIT) | C15: =_Actuals!C15 | D15: =_Actuals!D15 | E15: =_Actuals!E15 | F15: =_Actuals!F15 | G15: =G9-G11-G13 | H15: =H9-H11-H13 | I15: =I9-I11-I13 | J15: =J9-J11-J13 | K15: =K9-K11-K13 | L15: =L9-L11-L13 | M15: =M9-M11-M13 | N15: =N9-N11-N13 | ... AJ15: =AJ9-AJ11-AJ13
A16: Operating tax | C16: =_Actuals!C16 | D16: =_Actuals!D16 | E16: =_Actuals!E16 | F16: =_Actuals!F16 | G16: =G15*G17 | H16: =H15*H17 | I16: =I15*I17 | J16: =J15*J17 | K16: =K15*K17 | L16: =L15*L17 | M16: =M15*M17 | N16: =N15*N17 | ... AJ16: =AJ15*AJ17
A17: tax rate | C17: =IF(C15=0,"",C16/C15) | D17: =IF(D15=0,"",D16/D15) | E17: =IF(E15=0,"",E16/E15) | F17: =IF(F15=0,"",F16/F15) | G17: =F17 | H17: =G17 | I17: =H17 | J17: =I17 | K17: =J17 | L17: =K17 | M17: =L17 | N17: =M17 | ... AJ17: =AI17
A18: Operating income, after tax (OI) | C18: =_Actuals!C18 | D18: =_Actuals!D18 | E18: =_Actuals!E18 | F18: =_Actuals!F18 | G18: =G15-G16 | H18: =H15-H16 | I18: =I15-I16 | J18: =J15-J16 | K18: =K15-K16 | L18: =L15-L16 | M18: =M15-M16 | N18: =N15-N16 | ... AJ18: =AJ15-AJ16
A19: growth | D19: =IF(C18=0,"",D18/C18-1) | E19: =IF(D18=0,"",E18/D18-1) | F19: =IF(E18=0,"",F18/E18-1) | G19: =IF(F18=0,"",G18/F18-1) | H19: =IF(G18=0,"",H18/G18-1) | I19: =IF(H18=0,"",I18/H18-1) | J19: =IF(I18=0,"",J18/I18-1) | K19: =IF(J18=0,"",K18/J18-1) | ... AJ19: =IF(AI18=0,"",AJ18/AI18-1)
A20: Net financial expense (NFE) [imputed] | C20: =_Actuals!C20 | D20: =_Actuals!D20 | E20: =_Actuals!E20 | F20: =_Actuals!F20 | G20: =G62*F47 | H20: =H62*G47 | I20: =I62*H47 | J20: =J62*I47 | K20: =K62*J47 | L20: =L62*K47 | M20: =M62*L47 | N20: =N62*M47 | ... AJ20: =AJ62*AI47
A21: Net income (comprehensive) | C21: =_Actuals!C21 | D21: =_Actuals!D21 | E21: =_Actuals!E21 | F21: =_Actuals!F21 | G21: =G18-G20 | H21: =H18-H20 | I21: =I18-I20 | J21: =J18-J20 | K21: =K18-K20 | L21: =L18-L20 | M21: =M18-M20 | N21: =N18-N20 | ... AJ21: =AJ18-AJ20
A22: growth | D22: =IF(C21=0,"",D21/C21-1) | E22: =IF(D21=0,"",E21/D21-1) | F22: =IF(E21=0,"",F21/E21-1) | G22: =IF(F21=0,"",G21/F21-1) | H22: =IF(G21=0,"",H21/G21-1) | I22: =IF(H21=0,"",I21/H21-1) | J22: =IF(I21=0,"",J21/I21-1) | K22: =IF(J21=0,"",K21/J21-1) | ... AJ22: =IF(AI21=0,"",AJ21/AI21-1)
A23: Shares outstanding (mm) | C23: =_Actuals!C23 | D23: =_Actuals!D23 | E23: =_Actuals!E23 | F23: =_Actuals!F23 | G23: =IF($C$2="Enterprise",F23*(1-G24),F23) | H23: =IF($C$2="Enterprise",G23*(1-H24),G23) | I23: =IF($C$2="Enterprise",H23*(1-I24),H23) | J23: =IF($C$2="Enterprise",I23*(1-J24),I23) | K23: =IF($C$2="Enterprise",J23*(1-K24),J23) | L23: =IF($C$2="Enterprise",K23*(1-L24),K23) | M23: =IF($C$2="Enterprise",L23*(1-M24),L23) | N23: =IF($C$2="Enterprise",M23*(1-N24),M23) | ... AJ23: =IF($C$2="Enterprise",AI23*(1-AJ24),AI23)
A24: change | D24: =IF(C23=0,"",D23/C23-1) | E24: =IF(D23=0,"",E23/D23-1) | F24: =IF(E23=0,"",F23/E23-1) | H24: =G24 | I24: =H24 | J24: =I24 | K24: =J24 | L24: =K24 | M24: =L24 | N24: =M24 | O24: =N24 | ... AJ24: =AI24
A25: Earnings per share (EPS = NI ÷ shares) ← required | C25: =_Actuals!C25 | D25: =_Actuals!D25 | E25: =_Actuals!E25 | F25: =_Actuals!F25 | G25: =G21/G23 | H25: =H21/H23 | I25: =I21/I23 | J25: =J21/J23 | K25: =K21/K23 | L25: =L21/L23 | M25: =M21/M23 | N25: =N21/N23 | ... AJ25: =AJ21/AJ23
A26: growth | D26: =IF(C25=0,"",D25/C25-1) | E26: =IF(D25=0,"",E25/D25-1) | F26: =IF(E25=0,"",F25/E25-1) | G26: =IF(F25=0,"",G25/F25-1) | H26: =IF(G25=0,"",H25/G25-1) | I26: =IF(H25=0,"",I25/H25-1) | J26: =IF(I25=0,"",J25/I25-1) | K26: =IF(J25=0,"",K25/J25-1) | ... AJ26: =IF(AI25=0,"",AJ25/AI25-1)
A27: DISTRIBUTIONS
A28: Dividends per share (DPS) ← required | C28: =_Actuals!C28 | D28: =_Actuals!D28 | E28: =_Actuals!E28 | F28: =_Actuals!F28 | G28: =IF($C$2="Enterprise",IF(G23=0,"",(G21-(G48-F48)-G31)/G23),$E$2*G25) | H28: =IF($C$2="Enterprise",IF(H23=0,"",(H21-(H48-G48)-H31)/H23),$E$2*H25) | I28: =IF($C$2="Enterprise",IF(I23=0,"",(I21-(I48-H48)-I31)/I23),$E$2*I25) | J28: =IF($C$2="Enterprise",IF(J23=0,"",(J21-(J48-I48)-J31)/J23),$E$2*J25) | K28: =IF($C$2="Enterprise",IF(K23=0,"",(K21-(K48-J48)-K31)/K23),$E$2*K25) | L28: =IF($C$2="Enterprise",IF(L23=0,"",(L21-(L48-K48)-L31)/L23),$E$2*L25) | M28: =IF($C$2="Enterprise",IF(M23=0,"",(M21-(M48-L48)-M31)/M23),$E$2*M25) | N28: =IF($C$2="Enterprise",IF(N23=0,"",(N21-(N48-M48)-N31)/N23),$E$2*N25) | ... AJ28: =IF($C$2="Enterprise",IF(AJ23=0,"",(AJ21-(AJ48-AI48)-AJ31)/AJ23),$E$2*AJ25)
A29: payout ratio | C29: =IF(C25=0,"",C28/C25) | D29: =IF(D25=0,"",D28/D25) | E29: =IF(E25=0,"",E28/E25) | F29: =IF(F25=0,"",F28/F25) | G29: =IF(G25=0,"",G28/G25) | H29: =IF(H25=0,"",H28/H25) | I29: =IF(I25=0,"",I28/I25) | J29: =IF(J25=0,"",J28/J25) | ... AJ29: =IF(AJ25=0,"",AJ28/AJ25)
A30: Share price (constant P/B, off prior book) | F30: 21.12 | G30: =($F$30/($F$48/$F$23))*(F48/F23) | H30: =($F$30/($F$48/$F$23))*(G48/G23) | I30: =($F$30/($F$48/$F$23))*(H48/H23) | J30: =($F$30/($F$48/$F$23))*(I48/I23) | K30: =($F$30/($F$48/$F$23))*(J48/J23) | L30: =($F$30/($F$48/$F$23))*(K48/K23) | M30: =($F$30/($F$48/$F$23))*(L48/L23) | N30: =($F$30/($F$48/$F$23))*(M48/M23) | ... AJ30: =($F$30/($F$48/$F$23))*(AI48/AI23)
A31: Share repurchases ($) = shares retired × price | G31: =(F23-G23)*G30 | H31: =(G23-H23)*H30 | I31: =(H23-I23)*I30 | J31: =(I23-J23)*J30 | K31: =(J23-K23)*K30 | L31: =(K23-L23)*L30 | M31: =(L23-M23)*M30 | N31: =(M23-N23)*N30 | ... AJ31: =(AI23-AJ23)*AJ30
A32: CASH FLOW — to free cash flow to equity
A33: Operating income, after tax (OI) | C33: =_Actuals!C18 | D33: =_Actuals!D18 | E33: =_Actuals!E18 | F33: =_Actuals!F18 | G33: =G18 | H33: =H18 | I33: =I18 | J33: =J18 | K33: =K18 | L33: =L18 | M33: =M18 | N33: =N18 | ... AJ33: =AJ18
A34: Investment in NOA (−ΔNOA) | D34: =-(D46-C46) | E34: =-(E46-D46) | F34: =-(F46-E46) | G34: =-(G46-F46) | H34: =-(H46-G46) | I34: =-(I46-H46) | J34: =-(J46-I46) | K34: =-(K46-J46) | ... AJ34: =-(AJ46-AI46)
A35: Capital expenditure (capex) | D35: =(D49-C49)+D13 | E35: =(E49-D49)+E13 | F35: =(F49-E49)+F13 | G35: =G36*G6 | H35: =H36*H6 | I35: =I36*I6 | J35: =J36*J6 | K35: =K36*K6 | L35: =L36*L6 | M35: =M36*M6 | N35: =N36*N6 | ... AJ35: =AJ36*AJ6
A36: capex % of revenue | G36: =$F$35/$F$6 | H36: =G36 | I36: =H36 | J36: =I36 | K36: =J36 | L36: =K36 | M36: =L36 | N36: =M36 | O36: =N36 | ... AJ36: =AI36
A37: Free cash flow to firm (OI − ΔNOA) | D37: =D33+D34 | E37: =E33+E34 | F37: =F33+F34 | G37: =G33+G34 | H37: =H33+H34 | I37: =I33+I34 | J37: =J33+J34 | K37: =K33+K34 | ... AJ37: =AJ33+AJ34
A38: Net financial expense (−NFE) | C38: =-C20 | D38: =-D20 | E38: =-E20 | F38: =-F20 | G38: =-G20 | H38: =-H20 | I38: =-I20 | J38: =-J20 | ... AJ38: =-AJ20
A39: Net new borrowing (+ΔNFO) | D39: =D47-C47 | E39: =E47-D47 | F39: =F47-E47 | G39: =G47-F47 | H39: =H47-G47 | I39: =I47-H47 | J39: =J47-I47 | K39: =K47-J47 | ... AJ39: =AJ47-AI47
A40: Free cash flow to equity (FCFE) | D40: =D37+D38+D39 | E40: =E37+E38+E39 | F40: =F37+F38+F39 | G40: =G37+G38+G39 | H40: =H37+H38+H39 | I40: =I37+I38+I39 | J40: =J37+J38+J39 | K40: =K37+K38+K39 | ... AJ40: =AJ37+AJ38+AJ39
...

Sheet _Actuals
A1: PREPARED FINANCIALS (reformulated actuals) — source for the historical columns
C6: 120741 | D6: 122428 | E6: 122336 | F6: 125648
C8: 50848 | D8: 50123 | E8: 49221 | F8: 50820
C9: 69893 | D9: 72305 | E9: 73115 | F9: 74828
C11: 28961 | D11: 28874 | E11: 28411 | F11: 28942
C13: 18021 | D13: 18777 | E13: 20580 | F13: 20886
C15: 22911 | D15: 24654 | E15: 24124 | F15: 25000
C16: 4811.31 | D16: 5251.302 | E16: 6416.984 | F16: 3350
C18: 18099.69 | D18: 19402.698 | E18: 17707.016 | F18: 21650
C20: 4825.32 | D20: 5276.048 | E20: 4961.106 | F20: 5892.264
C21: 13274.37 | D21: 14126.65 | E21: 12745.91 | F21: 15757.736
C23: 7128 | D23: 7150.0634 | E23: 7175.8954 | F23: 7037.5024
C25: 1.8623 | D25: 1.9757 | E25: 1.7762 | F25: 2.2391
... C43: 149259 | D43: 149394 | E43: 149780 | F43: 154201

Sheet _Rates
A1: RATES — source (real cost of debt ρD)
C56: 0.02 | D56: 0.02 | E56: 0.02 | F56: 0.02 | G56: 0.016532 | H56: 0.025599 | I56: 0.031015 | J56: 0.034515 | K56: 0.036779 | L56: 0.038368 | M56: 0.039361 | N56: 0.040062 | O56: 0.040467 | P56: 0.040652 | Q56: 0.040925 | R56: 0.04107 | S56: 0.041109 | T56: 0.041215 | U56: 0.041248 | V56: 0.041389 | W56: 0.041501 | X56: 0.041636 | Y56: 0.041723 | Z56: 0.042002 | AA56: 0.04207 | AB56: 0.042369 | AC56: 0.042654 | AD56: 0.042949 | AE56: 0.043258 | AF56: 0.043815 | AG56: 0.04389 | AH56: 0.044206 | AI56: 0.044802 | AJ56: 0.045454
