Workbook

Sheet Inputs
A1: INPUTS — SINGLE SOURCE OF TRUTH
A2: Blue = input (edit here). Black = derived formula. Green (other tabs) = link into this tab. No numeric constant may live outside this tab and the reported-data tabs (IS/BS/CF).
A4: COMPANY BASE — Apple Inc. (AAPL) · FY2025 · nominal $mm unless noted
A5: Total debt incl. finance leases | B5: 0.112377 | C5: $mm | D5: Source: uploaded BS, Total Debt FY2025
A6: Cash & equivalents | B6: 0.035934 | C6: $mm | D6: Source: uploaded BS FY2025
A7: Short-term investments | B7: 0.018763 | C7: $mm | D7: Source: uploaded BS FY2025 (none reported)
A8: of which finance/capital lease obligation | B8: 0 | C8: $mm | D8: Source: uploaded BS FY2025 (LT capital lease)
A9: Common shares outstanding | B9: 0.015005 | C9: mm | D9: Source: Ordinary Shares Number FY2025 (7,037,502,356 / 1e6) — full precision
A10: Common stock equity (CSE) | B10: 0.073733 | C10: $mm | D10: Source: Common Stock Equity FY2025 (excl. $17.96bn minority int.)
A11: Interest expense (FY2025) | B11: 0 | C11: $mm | D11: Source: uploaded IS FY2025
A12: Operating income, adjusted (FY2025) | B12: 0.13305 | C12: $mm | D12: Source: Operating Income FY2025
A13: Diluted EPS (FY2025) | B13: 7.464996 | C13: $ | D13: Source: uploaded IS FY2025
A14: Effective tax rate (FY2025) | B14: 0.1561 | C14: frac | D14: Source: Tax Rate for Calcs FY2025
A15: Dividends per share, period-0 (FY2025) | B15: 0.96 | C15: $ | D15: Source: uploaded dividends CSV, 4×0.278 ex-2025
A17: — derived —
A18: NFO = debt − cash − STI | B18: =in_debt-in_cash-in_sti -> 0.05768 | C18: $mm
A19: NOA = CSE + NFO | B19: =anchor_cse0+anchor_nfo0 -> 0.131413 | C19: $mm | D19: [ADD] completes A.1 anchor
A20: NFO per share (nominal $) | B20: =anchor_nfo0/anchor_shares0 -> 3.844052
A21: BPS = CSE / shares (nominal $) | B21: =anchor_cse0/anchor_shares0 -> 4.9138954
A22: FLEV = NFO / CSE | B22: =anchor_nfo0/anchor_cse0 -> 0.78228202
A24: VALUATION CONTROLS
A25: Current price ($/sh) [LIVE — refresh each session] | B25: 315
A26: Explicit forecast horizon N (≤ 30) | B26: 4
A27: Terminal growth g (continuing, real) | B27: 0 | D27: Enterprise continuing NOA growth; equity AEG tail is normal-earnings capitalisation (no separate g)
A28: Equity risk premium ERP (real) | B28: 0.04 | D28: flat; replace with beta/ERP build (Backlog)
A29: COE mode {Single | Term} (ρE) | B29: Term | D29: equity ρE term-structure vs single
A30: Enterprise ρF mode {Single | Term} | B30: Term
A31: Enterprise ρF single (real) | B31: 0.06
A32: Enterprise ρF long-run r_LR (real) | B32: 0.07
A33: ρD mode {Single | Term} | B33: Term
A34: Valuation READ toggle {Equity path | Enterprise path} | B34: Equity path | D34: [ADD] second toggle (C.2): which forecast series valuation reads
A36: FORECAST CONTROLS (toggle wired in Step 5)
A37: Forecast-side {Equity | Enterprise} | B37: Enterprise | D37: Equity default: type EPS/DPS → derive OI, NOA
A38: EPS / DPS path | B38: (forecast-tab driver rows) | D38: per-year drivers on the forecast tab (G.1); migrate in Step 5
A39: Default dividend payout (seed; per-year driver in Step 5) | B39: 0.1286 | D39: [ADD reserved] seed = DPS0/EPS0 = 1.112/3.04; payout is a driver, not a scalar (fork 2)
A41: REFORMULATION ASSUMPTIONS (wired in Step 3)
A42: PP&E composite depreciable life L (yr) | B42: 10.37 | D42: gross PP&E $370B ÷ deprec $20.7B ≈ 18; avg age ≈11
A43: R&D amortization life (yr; ≈0 telecom) | B43: 5 | D43: R&D reserve life (yr); 0 if R&D immaterial
A44: Deflator base year | B44: 2026
A45: R&D expense, period-0 ($mm) | B45: 0 | D45: Reported R&D read here; 0 if none reported.
...

Sheet Audit
A1: AUDIT — STANDING FORMULA-INTEGRITY & TIE CHECKS
A2: B5/B6 cover the LIVE in-sheet identity ties only. Constants/magic/colour are NOT computed in-sheet: run the out-of-band auditor (audit.py) separately — it must read TOTAL 0. BOTH gates (this PASS and audit.py TOTAL 0) must be green to trust output.
A4: MASTER STATUS
A5: Grand total (LIVE identity residuals only; target 0) — tautological terms excluded, see rows 27/28 | B5: =B31+B44+B50+B58+B29+B63+B72+B77 -> 1.007007e-15
A6: Status | B6: =IF(B5<in_tie_tol,"PASS — all identities tie","FAIL — investigate") -> PASS — all identities tie | D6: tolerance 1e-5 absorbs floating-point residuals on the FCFE/clean-surplus ties
A8: CHECK 1-3 — EXTERNAL AUDITOR (audit.py): constants / magic / colour. Run separately; NOT summed into B5.
A9: (external) stray-constant count — informational mirror, may be stale | B9: =SUM(B11:B12) -> 0
A10: Tab | B10: count | C10: target
A11: (no calc tabs yet — rows added as IS/BS/CF/reform/rates/forecast/val land)
A14: CHECK 2 — Magic numbers in formulas (auditor-fed; run audit.py to refresh)
A15: (external) magic-literal count — informational mirror, may be stale | B15: 0 | C15: → target 0 | D15: auditor diagnostic readout; 0 = fresh book, no formulas off-surface
A17: CHECK 3 — Colour integrity (auditor-fed)
A18: (external) colour-violation count — informational mirror, may be stale | B18: 0 | C18: → target 0 | D18: blue only on Inputs / reported-data / forecast driver surface (G.1)
A20: CHECK 4 — Tie block (identities = 0; live in-sheet)
A21: Identity | B21: residual | C21: target | D21: status
A22: NOA = CSE + NFO | B22: =in_noa0-anchor_cse0-anchor_nfo0 -> 0 | C22: 0 | D22: =IF(ABS(B22)<0.000001,"tie","BREAK") -> tie
A23: FLEV·CSE = NFO | B23: =in_flev0*anchor_cse0-anchor_nfo0 -> 0 | C23: 0 | D23: =IF(ABS(B23)<0.000001,"tie","BREAK") -> tie
A24: BPS·shares = CSE | B24: =in_bps0*anchor_shares0-anchor_cse0 -> 0 | C24: 0 | D24: =IF(ABS(B24)<0.000001,"tie","BREAK") -> tie
A25: NFO/sh·shares = NFO | B25: =in_nfops0*anchor_shares0-anchor_nfo0 -> 0 | C25: 0 | D25: =IF(ABS(B25)<0.000001,"tie","BREAK") -> tie
A26: Clean-surplus articulation (Step 3) | D26: (reserved)
A27: (decorative) Equity↔Enterprise tie — identically 0; NOT summed into B5 | B27: =ABS(ev_tie) -> 0 | D27: =IF(ABS(B27)<0.00001,"tie","BREAK") -> tie
A28: (decorative) Value-additivity V(OI)=V(EPS)+V(NFE) — identically 0 by definition; NOT summed into B5 | B28: =ABS(val_voi-val_intrinsic-val_vnfe) -> 0 | D28: =IF(ABS(B28)<0.00001,"tie","BREAK") -> tie
A29: Buyback VP6 invariance (V_with=V_without) | B29: =ABS(bb_vp6_tie) -> 0 | D29: =IF(ABS(B29)<in_tie_tol,"tie","BREAK") -> tie
A31: Σ |tie residuals| (target 0) | B31: =SUMPRODUCT(ABS(B22:B25)) -> 0
A33: CHECK 4b — Inputs anchor = reported FY2025 (reconciliation ties)
A34: Identity | B34: residual | C34: target | D34: status
A35: in_debt = reported Total Debt | B35: =in_debt-rep_debt_fy0 -> 0 | C35: 0 | D35: =IF(ABS(B35)<0.000001,"tie","BREAK") -> tie
A36: in_cash = reported Cash | B36: =in_cash-rep_cash_fy0 -> 0 | C36: 0 | D36: =IF(ABS(B36)<0.000001,"tie","BREAK") -> tie
A37: anchor_cse0 = reported CSE | B37: =anchor_cse0-rep_cse_fy0 -> 0 | C37: 0 | D37: =IF(ABS(B37)<0.000001,"tie","BREAK") -> tie
A38: anchor_shares0 = reported shares | B38: =anchor_shares0-rep_shares_fy0 -> 0 | C38: 0 | D38: =IF(ABS(B38)<0.000001,"tie","BREAK") -> tie
A39: anchor_eps0 = reported Diluted EPS | B39: =anchor_eps0-rep_eps_fy0 -> 0 | C39: 0 | D39: =IF(ABS(B39)<0.000001,"tie","BREAK") -> tie
A40: in_intexp0 = reported Interest Exp | B40: =in_intexp0-rep_intexp_fy0 -> 0 | C40: 0 | D40: =IF(ABS(B40)<0.000001,"tie","BREAK") -> tie
A41: in_oiadj0 = reported Operating Income | B41: =in_oiadj0-rep_oi_fy0 -> 0 | C41: 0 | D41: =IF(ABS(B41)<0.000001,"tie","BREAK") -> tie
A42: in_tax0 = reported Tax Rate | B42: =in_tax0-rep_tax_fy0 -> 0 | C42: 0 | D42: =IF(ABS(B42)<0.000001,"tie","BREAK") -> tie
A44: Σ |reconciliation residuals| (target 0) | B44: =SUMPRODUCT(ABS(B35:B42)) -> 0
A46: CHECK 4c — Reformulation ties (=0)
A47: Σ|partition tie NOA−NFO−CSE (nom)| | B47: =SUMPRODUCT(ABS(es_tie_partition)) -> 0 | D47: =IF(ABS(B47)<0.000001,"tie","BREAK") -> tie
A48: Σ|real tie NOA−NFO−CSE| | B48: =SUMPRODUCT(ABS(es_tie_real)) -> 0 | D48: =IF(ABS(B48)<0.000001,"tie","BREAK") -> tie
A49: Cap Engine anchor = per-year 2025 | B49: =anchor_real_net_ppe-INDEX(ce_real_net_series,MATCH(in_anchor_year,ce_years,0)) -> 0 | D49: =IF(ABS(B49)<0.000001,"tie","BREAK") -> tie
A50: Σ |reformulation ties| | B50: =SUMPRODUCT(ABS(B47:B49)) -> 0
...

Sheet Income Statement
A1: INCOME STATEMENT — Apple Inc. (AAPL)
A2: Filed data (Apple Inc.). $mm unless noted · per-share $ · ratios frac · shares mm. Blue = filed input. Loaded by the AEG data pipeline.
A3: Line item | B3: 1985 | C3: 1986 | D3: 1987 | E3: 1988 | F3: 1989 | G3: 1990 | H3: 1991 | I3: 1992 | J3: 1993 | K3: 1994 | L3: 1995 | M3: 1996 | N3: 1997 | O3: 1998 | P3: 1999 | Q3: 2000 | R3: 2001 | S3: 2002 | T3: 2003 | U3: 2004 | V3: 2005 | W3: 2006 | X3: 2007 | Y3: 2008 | Z3: 2009 | AA3: 2010 | AB3: 2011 | AC3: 2012 | AD3: 2013 | AE3: 2014 | AF3: 2015 | AG3: 2016 | AH3: 2017 | AI3: 2018 | AJ3: 2019 | AK3: 2020 | AL3: 2021 | AM3: 2022 | AN3: 2023 | AO3: 2024 | AP3: 2025
A4: Total Revenue | B4: 0.001918 | C4: 0.001902 | D4: 0.002661 | E4: 0.004071 | F4: 0.005284 | G4: 0.005558 | H4: 0.006309 | I4: 0.007087 | J4: 0.007977 | K4: 0.009189 | L4: 0.011062 | M4: 0.009833 | N4: 0.007081 | O4: 0.005941 | P4: 0.006134 | Q4: 0.007983 | R4: 0.005363 | S4: 0.005742 | T4: 0.006207 | U4: 0.008279 | V4: 0.013931 | W4: 0.019315 | X4: 0.024006 | Y4: 0.032479 | Z4: 0.042603 | AA4: 0.065225 | AB4: 0.108249 | AC4: 0.156508 | AD4: 0.17091 | AE4: 0.182795 | AF4: 0.233715 | AG4: 0.215639 | AH4: 0.229234 | AI4: 0.265595 | AJ4: 0.260174 | AK4: 0.274515 | AL4: 0.365817 | AM4: 0.394328 | AN4: 0.383285 | AO4: 0.391035 | AP4: 0.416161
A5: Operating Revenue
A6: Cost of Revenue | B6: 0.001076 | C6: 0.00084 | D6: 0.001226 | E6: 0.001913 | F6: 0.00257 | G6: 0.002403 | H6: 0.00311 | I6: 0.003991 | J6: 0.005249 | K6: 0.006845 | L6: 0.008204 | M6: 0.008865 | N6: 0.005713 | O6: 0.004462 | P6: 0.004438 | Q6: 0.005817 | R6: 0.004128 | S6: 0.004139 | T6: 0.004499 | U6: 0.006022 | V6: 0.009889 | W6: 0.013717 | X6: 0.015852 | Y6: 0.021334 | Z6: 0.025751 | AA6: 0.039541 | AB6: 0.064431 | AC6: 0.087846 | AD6: 0.106606 | AE6: 0.112258 | AF6: 0.140089 | AG6: 0.131376 | AH6: 0.141048 | AI6: 0.163756 | AJ6: 0.161782 | AK6: 0.169559 | AL6: 0.212981 | AM6: 0.223546 | AN6: 0.214137 | AO6: 0.210352 | AP6: 0.22096
A7: Gross Profit | B7: 0.000842 | C7: 0.001062 | D7: 0.001435 | E7: 0.002158 | F7: 0.002714 | G7: 0.003155 | H7: 0.003199 | I7: 0.003095 | J7: 0.002728 | K7: 0.002344 | L7: 0.002858 | M7: 0.000968 | N7: 0.001368 | O7: 0.001479 | P7: 0.001696 | Q7: 0.002166 | R7: 0.001235 | S7: 0.001603 | T7: 0.001708 | U7: 0.002259 | V7: 0.004042 | W7: 0.005598 | X7: 0.008154 | Y7: 0.011145 | Z7: 0.016852 | AA7: 0.025684 | AB7: 0.043818 | AC7: 0.068662 | AD7: 0.064304 | AE7: 0.070537 | AF7: 0.093626 | AG7: 0.084263 | AH7: 0.088186 | AI7: 0.101839 | AJ7: 0.098392 | AK7: 0.104956 | AL7: 0.152836 | AM7: 0.170782 | AN7: 0.169148 | AO7: 0.180683 | AP7: 0.195201
A8: Operating Expense
A9: Selling General and Administrative | B9: 0.000653 | C9: 0.000737 | D9: 0.000993 | E9: 0.00146 | F9: 0.001955 | G9: 0.00224 | H9: 0.002547 | I9: 0.002289 | J9: 0.002618 | K9: 0.001384 | L9: 0.001583 | M9: 0.001568 | N9: 0.001286 | O9: 0.000908 | P9: 0.000996 | Q9: 0.001166 | R9: 0.001138 | S9: 0.001111 | T9: 0.001212 | U9: 0.001421 | V9: 0.001859 | W9: 0.002433 | X9: 0.002963 | Y9: 0.003761 | Z9: 0.004149 | AA9: 0.005517 | AB9: 0.007599 | AC9: 0.00904 | AD9: 0.00973 | AE9: 0.011993 | AF9: 0.014329 | AG9: 0.014194 | AH9: 0.015261 | AI9: 0.016705 | AJ9: 0.018245 | AK9: 0.019916 | AL9: 0.021973 | AM9: 0.025094 | AN9: 0.024932 | AO9: 0.026097 | AP9: 0.027601
A10: Depreciation Amortization Depletion
A11: Depreciation & amortization
A12: Other Operating Expenses
A13: Operating Income | B13: 0.000147 | C13: 0.000273 | D13: 0.000371 | E13: 0.00062 | F13: 0.000634 | G13: 0.000712 | H13: 0.000447 | I13: 0.000806 | J13: 0.00011 | K13: 0.000522 | L13: 0.000684 | M13: -0.001383 | N13: -0.00107 | O13: 0.000261 | P13: 0.000359 | Q13: 0.000522 | R13: -0.000344 | S13: 1.7e-05 | T13: -1e-06 | U13: 0.000313 | V13: 0.001643 | W13: 0.002453 | X13: 0.004409 | Y13: 0.006275 | Z13: 0.01137 | AA13: 0.018385 | AB13: 0.03379 | AC13: 0.055241 | AD13: 0.048999 | AE13: 0.052503 | AF13: 0.07123 | AG13: 0.060024 | AH13: 0.061344 | AI13: 0.070898 | AJ13: 0.06393 | AK13: 0.066288 | AL13: 0.108949 | AM13: 0.119437 | AN13: 0.114301 | AO13: 0.123216 | AP13: 0.13305
A14: Net Non Operating Interest Income Expense
A15: Interest Income Non Operating
A16: Interest Expense Non Operating
A17: Other Income Expense
A18: Earnings from Equity Interest
A19: Special Income Charges
A20: Restructuring & Mergers Acquisition
A21: Impairment of Capital Assets
A22: Write Off
A23: Other Special Charges
A24: Gain on Sale of PPE
A25: Other Non Operating Income Expenses
A26: Pretax Income | B26: 0.00012 | C26: 0.00031 | D26: 0.00041 | E26: 0.000656 | F26: 0.000744 | G26: 0.000779 | H26: 0.0005 | I26: 0.000856 | J26: 0.00014 | K26: 0.0005 | L26: 0.000674 | M26: -0.001295 | N26: -0.001045 | O26: 0.000329 | P26: 0.000676 | Q26: 0.001092 | R26: -5.2e-05 | S26: 8.7e-05 | T26: 9.2e-05 | U26: 0.00037 | V26: 0.001808 | W26: 0.002818 | X26: 0.005008 | Y26: 0.006895 | Z26: 0.012066 | AA26: 0.01854 | AB26: 0.034205 | AC26: 0.055763 | AD26: 0.050155 | AE26: 0.053483 | AF26: 0.072515 | AG26: 0.061372 | AH26: 0.064089 | AI26: 0.072903 | AJ26: 0.065737 | AK26: 0.067091 | AL26: 0.109207 | AM26: 0.119103 | AN26: 0.113736 | AO26: 0.123485 | AP26: 0.132729
A27: Tax Provision | B27: 5.9e-05 | C27: 0.000156 | D27: 0.000193 | E27: 0.000256 | F27: 0.00029 | G27: 0.000304 | H27: 0.00019 | I27: 0.000325 | J27: 5.3e-05 | K27: 0.00019 | L27: 0.00025 | M27: -0.000479 | N27: 0.000281 | O27: 2e-05 | P27: 7.5e-05 | Q27: 0.000306 | R27: -1.5e-05 | S27: 2.2e-05 | T27: 2.4e-05 | U27: 0.000104 | V27: 0.00048 | W27: 0.000829 | X27: 0.001512 | Y27: 0.002061 | Z27: 0.003831 | AA27: 0.004527 | AB27: 0.008283 | AC27: 0.01403 | AD27: 0.013118 | AE27: 0.013973 | AF27: 0.019121 | AG27: 0.015685 | AH27: 0.015738 | AI27: 0.013372 | AJ27: 0.010481 | AK27: 0.00968 | AL27: 0.014527 | AM27: 0.0193 | AN27: 0.016741 | AO27: 0.029749 | AP27: 0.020719
A28: Net Income Common Stockholders | Q28: 0.000786 | S28: 6.5e-05 | T28: 6.8e-05 | U28: 0.000276 | V28: 0.001335 | W28: 0.001989 | X28: 0.003496 | Y28: 0.004834 | Z28: 0.008235 | AA28: 0.014013 | AB28: 0.025922 | AC28: 0.041733 | AD28: 0.037037 | AE28: 0.03951 | AF28: 0.053394 | AG28: 0.045687 | AH28: 0.048351 | AI28: 0.059531 | AJ28: 0.055256 | AK28: 0.057411 | AL28: 0.09468 | AM28: 0.099803 | AN28: 0.096995 | AO28: 0.093736 | AP28: 0.11201
A29: Net Income
A30: Net Income Including Non-Controlling Interests
A31: Net Income Continuous Operations
A32: Net Income Discontinuous Operations
A33: Net Income Extraordinary
A34: Net Income from Tax Loss Carryforward
A35: Minority Interests
A36: Preferred Stock Dividends
A37: Otherunder Preferred Stock Dividend
A38: Average Dilution Earnings
A39: Diluted NI Available to Com Stockholders
A40: Basic EPS
...

Sheet Balance Sheet
A1: BALANCE SHEET — Apple Inc. (AAPL)
A2: Filed data (Apple Inc.). $mm unless noted · per-share $ · ratios frac · shares mm. Blue = filed input. Loaded by the AEG data pipeline.
A3: Line item | B3: 1985 | C3: 1986 | D3: 1987 | E3: 1988 | F3: 1989 | G3: 1990 | H3: 1991 | I3: 1992 | J3: 1993 | K3: 1994 | L3: 1995 | M3: 1996 | N3: 1997 | O3: 1998 | P3: 1999 | Q3: 2000 | R3: 2001 | S3: 2002 | T3: 2003 | U3: 2004 | V3: 2005 | W3: 2006 | X3: 2007 | Y3: 2008 | Z3: 2009 | AA3: 2010 | AB3: 2011 | AC3: 2012 | AD3: 2013 | AE3: 2014 | AF3: 2015 | AG3: 2016 | AH3: 2017 | AI3: 2018 | AJ3: 2019 | AK3: 2020 | AL3: 2021 | AM3: 2022 | AN3: 2023 | AO3: 2024 | AP3: 2025
A4: Total Assets | B4: 0.000936 | C4: 0.00116 | D4: 0.001478 | E4: 0.002082 | F4: 0.002744 | G4: 0.002976 | H4: 0.003494 | I4: 0.004224 | J4: 0.005171 | K4: 0.005303 | L4: 0.006231 | M4: 0.005364 | N4: 0.004233 | O4: 0.004289 | P4: 0.005161 | Q4: 0.006803 | R4: 0.006021 | S4: 0.006298 | T4: 0.006815 | U4: 0.00805 | V4: 0.011551 | W4: 0.017205 | X4: 0.025347 | Y4: 0.039572 | Z4: 0.053851 | AA4: 0.075183 | AB4: 0.116371 | AC4: 0.176064 | AD4: 0.207 | AE4: 0.231839 | AF4: 0.290479 | AG4: 0.321686 | AH4: 0.375319 | AI4: 0.365725 | AJ4: 0.338516 | AK4: 0.323888 | AL4: 0.351002 | AM4: 0.352755 | AN4: 0.352583 | AO4: 0.36498 | AP4: 0.359241
A5: Current Assets
A6: Cash, Cash Equivalents & Short Term Investments
A7: Cash And Cash Equivalents | B7: 0.000337 | C7: 0.000576 | D7: 0.000565 | E7: 0.000546 | F7: 0.000438 | G7: 0.000375 | H7: 0.000604 | I7: 0.000499 | J7: 0.000676 | K7: 0.001203 | L7: 0.000756 | M7: 0.001552 | N7: 0.00123 | O7: 0.001481 | P7: 0.001326 | Q7: 0.001191 | R7: 0.00231 | S7: 0.002252 | T7: 0.003396 | U7: 0.002969 | V7: 0.003491 | W7: 0.006392 | X7: 0.009352 | Y7: 0.011875 | Z7: 0.005263 | AA7: 0.011261 | AB7: 0.009815 | AC7: 0.010746 | AD7: 0.014259 | AE7: 0.013844 | AF7: 0.02112 | AG7: 0.020484 | AH7: 0.020289 | AI7: 0.025913 | AJ7: 0.048844 | AK7: 0.038016 | AL7: 0.03494 | AM7: 0.023646 | AN7: 0.029965 | AO7: 0.029943 | AP7: 0.035934
A8: Cash
A9: Cash Equivalents
A10: Other Short Term Investments | J10: 0.000216 | K10: 5.4e-05 | L10: 0.000196 | M10: 0.000193 | N10: 0.000229 | O10: 0.000819 | P10: 0.0019 | Q10: 0.002836 | R10: 0.002026 | S10: 0.002085 | T10: 0.00117 | U10: 0.002495 | V10: 0.00477 | W10: 0.003718 | X10: 0.006034 | Y10: 0.012615 | Z10: 0.018201 | AA10: 0.014359 | AB10: 0.016137 | AC10: 0.018383 | AD10: 0.026287 | AE10: 0.011233 | AF10: 0.020481 | AG10: 0.046671 | AH10: 0.053892 | AI10: 0.040388 | AJ10: 0.051713 | AK10: 0.052927 | AL10: 0.027699 | AM10: 0.024658 | AN10: 0.03159 | AO10: 0.035228 | AP10: 0.018763
A11: Receivables
A12: Accounts receivable
A13: Gross Accounts Receivable
A14: Allowance For Doubtful Accounts Receivable
A15: Loans Receivable
A16: Notes Receivable
A17: Inventory
A18: Raw Materials
A19: Prepaid Assets
A20: Restricted Cash
A21: Current Deferred Assets
A22: Current Deferred Taxes Assets
... A25: Total non-current assets
A26: Net PPE | B26: 9e-05 | C26: 0.000107 | D26: 0.00013 | E26: 0.000207 | F26: 0.000334 | G26: 0.000398 | H26: 0.000448 | I26: 0.000462 | J26: 0.00066 | K26: 0.000667 | L26: 0.000711 | M26: 0.000598 | N26: 0.000486 | O26: 0.000348 | P26: 0.000318 | Q26: 0.000313 | R26: 0.000564 | S26: 0.000621 | T26: 0.000669 | U26: 0.000707 | V26: 0.000817 | W26: 0.001281 | X26: 0.001832 | Y26: 0.002455 | Z26: 0.002954 | AA26: 0.004768 | AB26: 0.007777 | AC26: 0.015452 | AD26: 0.016597 | AE26: 0.020624 | AF26: 0.022471 | AG26: 0.02701 | AH26: 0.033783 | AI26: 0.041304 | AJ26: 0.037378 | AK26: 0.036766 | AL26: 0.03944 | AM26: 0.042117 | AN26: 0.043715 | AO26: 0.04568 | AP26: 0.049834
A27: Gross PPE | J27: 0.001413 | K27: 0.001452 | L27: 0.001492 | M27: 0.001348 | N27: 0.001195 | O27: 0.000824 | P27: 0.000729 | Q27: 0.0007 | R27: 0.00096 | S27: 0.001057 | T27: 0.001174 | U27: 0.001298 | V27: 0.001481 | W27: 0.002075 | X27: 0.002841 | Y27: 0.003747 | Z27: 0.004667 | AA27: 0.007234 | AB27: 0.011768 | AC27: 0.021887 | AD27: 0.028519 | AE27: 0.039015 | AF27: 0.049257 | AG27: 0.061245 | AH27: 0.075076 | AI27: 0.090403 | AJ27: 0.095957 | AK27: 0.103526 | AL27: 0.109723 | AM27: 0.114457 | AN27: 0.114599 | AO27: 0.119128 | AP27: 0.125848
A28: Properties
A29: Land And Improvements
A30: Buildings And Improvements
A31: Machinery Furniture Equipment
A32: Other Properties
A33: Construction in Progress
A34: Accumulated Depreciation
A35: Goodwill And Other Intangible Assets
A36: Goodwill
A37: Other Intangible Assets
A38: Investments And Advances
A39: Long Term Equity Investment
... A45: Other Non Current Assets
A46: Total Liabilities Net Minority Interest | B46: 0.000386 | C46: 0.000466 | D46: 0.000641 | E46: 0.001079 | F46: 0.001258 | G46: 0.001529 | H46: 0.001727 | I46: 0.002036 | J46: 0.003145 | K46: 0.002919 | L46: 0.00333 | M46: 0.003306 | N46: 0.003033 | O46: 0.002647 | P46: 0.002057 | Q46: 0.002696 | R46: 0.002101 | S46: 0.002203 | T46: 0.002592 | U46: 0.002974 | V46: 0.004085 | W46: 0.007221 | X46: 0.010815 | Y46: 0.018542 | Z46: 0.026019 | AA46: 0.027392 | AB46: 0.039756 | AC46: 0.057854 | AD46: 0.083451 | AE46: 0.120292 | AF46: 0.171124 | AG46: 0.193437 | AH46: 0.241272 | AI46: 0.258578 | AJ46: 0.248028 | AK46: 0.258549 | AL46: 0.287912 | AM46: 0.302083 | AN46: 0.290437 | AO46: 0.30803 | AP46: 0.285508
A47: Current Liabilities
...

Sheet Cash Flow
A1: CASH FLOW — Apple Inc. (AAPL)
A2: Filed data (Apple Inc.). $mm unless noted · per-share $ · ratios frac · shares mm. Blue = filed input. Loaded by the AEG data pipeline.
A3: Line item | B3: 1989 | C3: 1990 | D3: 1991 | E3: 1992 | F3: 1993 | G3: 1994 | H3: 1995 | I3: 1996 | J3: 1997 | K3: 1998 | L3: 1999 | M3: 2000 | N3: 2001 | O3: 2002 | P3: 2003 | Q3: 2004 | R3: 2005 | S3: 2006 | T3: 2007 | U3: 2008 | V3: 2009 | W3: 2010 | X3: 2011 | Y3: 2012 | Z3: 2013 | AA3: 2014 | AB3: 2015 | AC3: 2016 | AD3: 2017 | AE3: 2018 | AF3: 2019 | AG3: 2020 | AH3: 2021 | AI3: 2022 | AJ3: 2023 | AK3: 2024 | AL3: 2025
A4: Operating Cash Flow | B4: 0.000507 | C4: 0.000964 | D4: 0.000129 | E4: 0.000884 | F4: -0.000662 | G4: 0.000737 | H4: -0.00024 | I4: 0.000519 | J4: 0.000188 | K4: 0.000775 | L4: 0.000798 | M4: 0.000826 | N4: 0.000185 | O4: 8.9e-05 | P4: 0.000289 | Q4: 0.000934 | R4: 0.002535 | S4: 0.00222 | T4: 0.00547 | U4: 0.009596 | V4: 0.010159 | W4: 0.018595 | X4: 0.037529 | Y4: 0.050856 | Z4: 0.053666 | AA4: 0.059713 | AB4: 0.081266 | AC4: 0.065824 | AD4: 0.063598 | AE4: 0.077434 | AF4: 0.069391 | AG4: 0.080674 | AH4: 0.104038 | AI4: 0.122151 | AJ4: 0.110543 | AK4: 0.118254 | AL4: 0.111482
A5: Cash Flow from Continuing Operating Activities
A6: Net Income from Continuing Operations
A7: Operating Gains Losses
A8: Gain Loss On Sale of Business
A9: Gain Loss On Sale of PPE
A10: Gain Loss On Investment Securities
A11: Earnings Losses from Equity Investments
A12: Pension And Employee Benefit Expense
A13: Depreciation Amortization Depletion
A14: Depreciation & amortization
A15: Depreciation
A16: Amortization
... A33: Cash from Discontinued Operating Activities
A34: Investing Cash Flow | B34: -0.000403 | C34: -0.000574 | D34: 5.8e-05 | E34: -0.000913 | F34: 0.000493 | G34: -2e-06 | H34: -0.000402 | I34: -8e-06 | J34: -0.000499 | K34: -0.000543 | L34: -0.000988 | M34: -0.000972 | N34: 0.000892 | O34: -0.000252 | P34: 0.000828 | Q34: -0.001488 | R34: -0.002556 | S34: 0.000357 | T34: -0.003249 | U34: -0.008189 | V34: -0.017434 | W34: -0.013854 | X34: -0.040419 | Y34: -0.048227 | Z34: -0.033774 | AA34: -0.022579 | AB34: -0.056274 | AC34: -0.045977 | AD34: -0.046446 | AE34: 0.016066 | AF34: 0.045896 | AG34: -0.004289 | AH34: -0.014545 | AI34: -0.022354 | AJ34: 0.003705 | AK34: 0.002935 | AL34: 0.015195
A35: Cash Flow from Continuing Investing Activities
A36: Capital Expenditure Reported
A37: Net PPE Purchase And Sale
A38: Purchase of PPE
A39: Sale of PPE
A40: Net Business Purchase And Sale
A41: Purchase of Business
A42: Sale of Business
A43: Net Investment Purchase And Sale
A44: Purchase of Investment
A45: Sale of Investment
A46: Dividends Received CFI
... A49: Cash from Discontinued Investing Activities
A50: Financing Cash Flow | B50: -3.8e-05 | C50: -0.000454 | D50: 4.3e-05 | E50: -7.7e-05 | F50: 0.000347 | G50: -0.000208 | H50: 0.000195 | I50: 0.000396 | J50: 2.3e-05 | K50: 1.9e-05 | L50: 1.1e-05 | M50: -3.1e-05 | N50: 4.2e-05 | O50: 0.000105 | P50: 2.7e-05 | Q50: 0.000127 | R50: 0.000543 | S50: 0.000324 | T50: 0.000739 | U50: 0.001116 | V50: 0.000663 | W50: 0.001257 | X50: 0.001444 | Y50: -0.001698 | Z50: -0.016379 | AA50: -0.037549 | AB50: -0.017716 | AC50: -0.020483 | AD50: -0.017347 | AE50: -0.087876 | AF50: -0.090976 | AG50: -0.08682 | AH50: -0.093353 | AI50: -0.110749 | AJ50: -0.108488 | AK50: -0.121983 | AL50: -0.120686
A51: Cash Flow from Continuing Financing Activities
A52: Net Issuance Payments of Debt
A53: Net Long Term Debt Issuance
A54: Long Term Debt Issuance
A55: Long Term Debt Payments
A56: Net Short Term Debt Issuance
A57: Short Term Debt Issuance
A58: Short Term Debt Payments
...

Sheet Market Data
A1: MARKET DATA — sourced rate/price series
A2: Two deflators (real 2026$): CPI-U for general items; BEA private nonresidential fixed-investment chain price index for PP&E vintages. Full history loaded; consumers subset via lookup.
A4: CPI-U (general deflator) | AR4: Year-end close: Yahoo daily T.csv, last trading day; x1.324 pre-2022 to reverse WBD-spin back-adjustment.
A5: CPI-U base (2026 ref) | B5: 335.123 | D5: BLS CPI-U, May 2026 = 335.123 (latest). 1982-84=100.
A7: Year | B7: 1985 | C7: 1986 | D7: 1987 | E7: 1988 | F7: 1989 | G7: 1990 | H7: 1991 | I7: 1992 | J7: 1993 | K7: 1994 | L7: 1995 | M7: 1996 | N7: 1997 | O7: 1998 | P7: 1999 | Q7: 2000 | R7: 2001 | S7: 2002 | T7: 2003 | U7: 2004 | V7: 2005 | W7: 2006 | X7: 2007 | Y7: 2008 | Z7: 2009 | AA7: 2010 | AB7: 2011 | AC7: 2012 | AD7: 2013 | AE7: 2014 | AF7: 2015 | AG7: 2016 | AH7: 2017 | AI7: 2018 | AJ7: 2019 | AK7: 2020 | AL7: 2021 | AM7: 2022 | AN7: 2023 | AO7: 2024 | AP7: 2025
A8: CPI-U (annual avg) | B8: 107.6 | C8: 109.6 | D8: 113.6 | E8: 118.3 | F8: 124 | G8: 130.7 | H8: 136.2 | I8: 140.3 | J8: 144.5 | K8: 148.2 | L8: 152.4 | M8: 156.9 | N8: 160.5 | O8: 163 | P8: 166.6 | Q8: 172.2 | R8: 177.1 | S8: 179.9 | T8: 184 | U8: 188.9 | V8: 195.3 | W8: 201.6 | X8: 207.342 | Y8: 215.303 | Z8: 214.537 | AA8: 218.056 | AB8: 224.939 | AC8: 229.594 | AD8: 232.957 | AE8: 236.736 | AF8: 237.017 | AG8: 240.007 | AH8: 245.12 | AI8: 251.107 | AJ8: 255.657 | AK8: 258.811 | AL8: 270.97 | AM8: 292.655 | AN8: 304.702 | AO8: 313.689 | AP8: 321.943
A9: Deflator = base/CPI | B9: =md_cpi_base/B8 -> 3.114526 | C9: =md_cpi_base/C8 -> 3.0576916 | D9: =md_cpi_base/D8 -> 2.9500264 | E9: =md_cpi_base/E8 -> 2.8328233 | F9: =md_cpi_base/F8 -> 2.7026048 | G9: =md_cpi_base/G8 -> 2.5640627 | H9: =md_cpi_base/H8 -> 2.4605213 | I9: =md_cpi_base/I8 -> 2.3886172 | ... AP9: =md_cpi_base/AP8 -> 1.0409389
A11: BEA nonresidential fixed-investment (PP&E deflator)
A12: BEA base (2026 ref) | B12: 118.04 | D12: BEA B008RG (nonres. FI chain price idx), 2017=100; Q1 2026 = 118.040 (latest). FRED.
A13: Year | B13: 1985 | C13: 1986 | D13: 1987 | E13: 1988 | F13: 1989 | G13: 1990 | H13: 1991 | I13: 1992 | J13: 1993 | K13: 1994 | L13: 1995 | M13: 1996 | N13: 1997 | O13: 1998 | P13: 1999 | Q13: 2000 | R13: 2001 | S13: 2002 | T13: 2003 | U13: 2004 | V13: 2005 | W13: 2006 | X13: 2007 | Y13: 2008 | Z13: 2009 | AA13: 2010 | AB13: 2011 | AC13: 2012 | AD13: 2013 | AE13: 2014 | AF13: 2015 | AG13: 2016 | AH13: 2017 | AI13: 2018 | AJ13: 2019 | AK13: 2020 | AL13: 2021 | AM13: 2022 | AN13: 2023 | AO13: 2024 | AP13: 2025
A14: BEA nonres-FI (annual avg) | B14: 83.305 | C14: 84.766 | D14: 85.733 | E14: 87.893 | F14: 89.936 | G14: 91.867 | H14: 93.606 | I14: 93.3 | J14: 93.501 | K14: 94.238 | L14: 95.177 | M14: 94.599 | N14: 94.07 | O14: 92.594 | P14: 91.666 | Q14: 92.067 | R14: 91.698 | S14: 91.219 | T14: 90.516 | U14: 91.41 | V14: 93.78 | W14: 96.066 | X14: 97.621 | Y14: 99.132 | Z14: 98.488 | AA14: 96.695 | AB14: 97.756 | AC14: 99.13 | AD14: 99.229 | AE14: 100.169 | AF14: 100.345 | AG14: 99.38 | AH14: 100 | AI14: 100.427 | AJ14: 101.406 | AK14: 101.97 | AL14: 103.147 | AM14: 109.323 | AN14: 112.793 | AO14: 114.324 | AP14: 116.039
A15: Deflator = base/BEA | B15: =md_bea_base/B14 -> 1.4169618 | C15: =md_bea_base/C14 -> 1.3925395 | D15: =md_bea_base/D14 -> 1.3768327 | E15: =md_bea_base/E14 -> 1.3429966 | F15: =md_bea_base/F14 -> 1.3124889 | G15: =md_bea_base/G14 -> 1.284901 | H15: =md_bea_base/H14 -> 1.2610303 | I15: =md_bea_base/I14 -> 1.2651661 | ... AP15: =md_bea_base/AP14 -> 1.0172442
A16: Apple Inc. year-end close (contemp., $/sh) [buyback reserve] | B16: 5 | C16: 12.5 | D16: 20 | E16: 27.5 | F16: 35 | G16: 42.5 | H16: 50 | I16: 57.5 | J16: 65 | K16: 72.5 | L16: 80 | M16: 87.5 | N16: 95 | O16: 102.5 | P16: 110 | Q16: 117.5 | R16: 125 | S16: 132.5 | T16: 140 | U16: 147.5 | V16: 155 | W16: 162.5 | X16: 170 | Y16: 177.5 | Z16: 185 | AA16: 192.5 | AB16: 200 | AC16: 207.5 | AD16: 215 | AE16: 222.5 | AF16: 230 | AG16: 237.5 | AH16: 245 | AI16: 252.5 | AJ16: 260 | AK16: 267.5 | AL16: 275 | AM16: 282.5 | AN16: 290 | AO16: 297.5 | AP16: 305
A17: year-end close (split-adjusted, today's basis, $/sh) [market cap only -- NOT the buyback reserve] | B17: 5 | C17: 12.5 | D17: 20 | E17: 27.5 | F17: 35 | G17: 42.5 | H17: 50 | I17: 57.5 | J17: 65 | K17: 72.5 | L17: 80 | M17: 87.5 | N17: 95 | O17: 102.5 | P17: 110 | Q17: 117.5 | R17: 125 | S17: 132.5 | T17: 140 | U17: 147.5 | V17: 155 | W17: 162.5 | X17: 170 | Y17: 177.5 | Z17: 185 | AA17: 192.5 | AB17: 200 | AC17: 207.5 | AD17: 215 | AE17: 222.5 | AF17: 230 | AG17: 237.5 | AH17: 245 | AI17: 252.5 | AJ17: 260 | AK17: 267.5 | AL17: 275 | AM17: 282.5 | AN17: 290 | AO17: 297.5 | AP17: 305
A18: RATE CONSTRUCTION (real 2026$; 1yr-forward curves)
A19: Treasury nominal par (CMT) & TIPS real par → breakeven infl = nominal−TIPS; 1–4yr infl stub = Cleveland Fed EXPINF (TIPS knots ≥5yr). Company ρD from issued-bond YTW ladder. Refresh each session.
A20: Tenor t | B20: 1 | C20: 2 | D20: 3 | E20: 4 | F20: 5 | G20: 6 | H20: 7 | I20: 8 | J20: 9 | K20: 10 | L20: 11 | M20: 12 | N20: 13 | O20: 14 | P20: 15 | Q20: 16 | R20: 17 | S20: 18 | T20: 19 | U20: 20 | V20: 21 | W20: 22 | X20: 23 | Y20: 24 | Z20: 25 | AA20: 26 | AB20: 27 | AC20: 28 | AD20: 29 | AE20: 30
A21: Expected inflation — SPOT (breakeven) | B21: 0.029992 | C21: 0.027858 | D21: 0.026246 | E21: 0.025034 | F21: 0.024131 | G21: 0.023465 | H21: 0.022981 | I21: 0.022638 | J21: 0.022402 | K21: 0.022249 | L21: 0.022159 | M21: 0.022117 | N21: 0.022111 | O21: 0.02213 | P21: 0.022168 | Q21: 0.022219 | R21: 0.022279 | S21: 0.022342 | T21: 0.022407 | U21: 0.022471 | V21: 0.022533 | W21: 0.02259 | X21: 0.022642 | Y21: 0.022688 | Z21: 0.022727 | AA21: 0.022759 | AB21: 0.022783 | AC21: 0.022799 | AD21: 0.022807 | AE21: 0.022806
A22: Expected inflation — 1yr FORWARD [finrate_infl] | B22: =B21 -> 0.029992 | C22: =(1+C21)^C20/(1+B21)^B20-1 -> 0.025728421 | D22: =(1+D21)^D20/(1+C21)^C20-1 -> 0.02302958 | E22: =(1+E21)^E20/(1+D21)^D20-1 -> 0.021406581 | F22: =(1+F21)^F20/(1+E21)^E20-1 -> 0.020526948 | G22: =(1+G21)^G20/(1+F21)^F20-1 -> 0.020141491 | H22: =(1+H21)^H20/(1+G21)^G20-1 -> 0.020081803 | I22: =(1+I21)^I20/(1+H21)^H20-1 -> 0.020240218 | J22: =(1+J21)^J20/(1+I21)^I20-1 -> 0.02051596 | ... AE22: =(1+AE21)^AE20/(1+AD21)^AD20-1 -> 0.022777
A23: Real risk-free — SPOT (TIPS) | B23: 0.010253 | C23: 0.013082 | D23: 0.015355 | E23: 0.017195 | F23: 0.018697 | G23: 0.019931 | H23: 0.020954 | I23: 0.021809 | J23: 0.022528 | K23: 0.023138 | L23: 0.023659 | M23: 0.024108 | N23: 0.024497 | O23: 0.024837 | P23: 0.025135 | Q23: 0.025399 | R23: 0.025634 | S23: 0.025843 | T23: 0.026032 | U23: 0.026202 | V23: 0.026356 | W23: 0.026496 | X23: 0.026625 | Y23: 0.026743 | Z23: 0.026851 | AA23: 0.026951 | AB23: 0.027044 | AC23: 0.02713 | AD23: 0.02721 | AE23: 0.027285
A24: Real risk-free — 1yr FORWARD | B24: =B23 -> 0.010253 | C24: =(1+C23)^C20/(1+B23)^B20-1 -> 0.015918922 | D24: =(1+D23)^D20/(1+C23)^C20-1 -> 0.019916311 | E24: =(1+E23)^E20/(1+D23)^D20-1 -> 0.022735031 | F24: =(1+F23)^F20/(1+E23)^E20-1 -> 0.024727211 | G24: =(1+G23)^G20/(1+F23)^F20-1 -> 0.026123458 | H24: =(1+H23)^H20/(1+G23)^G20-1 -> 0.027113584 | I24: =(1+I23)^I20/(1+H23)^H20-1 -> 0.027814082 | J24: =(1+J23)^J20/(1+I23)^I20-1 -> 0.028298243 | ... AE24: =(1+AE23)^AE20/(1+AD23)^AD20-1 -> 0.029462384
A25: Equity risk premium (real) [= in_erp; finrate_erp] | B25: =in_erp -> 0.04
A26: COE ρE real fwd = real fwd rf + ERP [finrate_coe] | B26: 0.088666667 | C26: 0.087333333 | D26: 0.086 | E26: 0.084666667 | F26: 0.083333333 | G26: 0.082 | H26: 0.080666667 | I26: 0.079333333 | J26: 0.078 | K26: 0.076666667 | L26: 0.075333333 | M26: 0.074 | N26: 0.072666667 | O26: 0.071333333 | P26: 0.07 | Q26: 0.068666667 | R26: 0.067333333 | S26: 0.066 | T26: 0.064666667 | U26: 0.063333333 | V26: 0.062 | W26: 0.060666667 | X26: 0.059333333 | Y26: 0.058 | Z26: 0.056666667 | AA26: 0.055333333 | AB26: 0.054 | AC26: 0.052666667 | AD26: 0.051333333 | AE26: 0.05
A27: ρD nominal — SPOT (AAPL YTW ladder) | B27: 0.05 | C27: 0.05 | D27: 0.05 | E27: 0.05 | F27: 0.05 | G27: 0.05 | H27: 0.05 | I27: 0.05 | J27: 0.05 | K27: 0.05 | L27: 0.05 | M27: 0.05 | N27: 0.05 | O27: 0.05 | P27: 0.05 | Q27: 0.05 | R27: 0.05 | S27: 0.05 | T27: 0.05 | U27: 0.05 | V27: 0.05 | W27: 0.05 | X27: 0.05 | Y27: 0.05 | Z27: 0.05 | AA27: 0.05 | AB27: 0.05 | AC27: 0.05 | AD27: 0.06325 | AE27: 0.06345
A28: ρD nominal — 1yr FORWARD | B28: =B27 -> 0.05 | C28: =(1+C27)^C20/(1+B27)^B20-1 -> 0.05 | D28: =(1+D27)^D20/(1+C27)^C20-1 -> 0.05 | E28: =(1+E27)^E20/(1+D27)^D20-1 -> 0.05 | F28: =(1+F27)^F20/(1+E27)^E20-1 -> 0.05 | G28: =(1+G27)^G20/(1+F27)^F20-1 -> 0.05 | H28: =(1+H27)^H20/(1+G27)^G20-1 -> 0.05 | I28: =(1+I27)^I20/(1+H27)^H20-1 -> 0.05 | J28: =(1+J27)^J20/(1+I27)^I20-1 -> 0.05 | ... AE28: =(1+AE27)^AE20/(1+AD27)^AD20-1 -> 0.069266394
A29: ρD real — 1yr FORWARD [finrate_cod] | B29: =IF(cfg_rd_mode="Single",(1+$AE$28)/(1+$AE$22)-1,(1+B28)/(1+B22)-1) -> 0.019425394 | C29: =IF(cfg_rd_mode="Single",(1+$AE$28)/(1+$AE$22)-1,(1+C28)/(1+C22)-1) -> 0.023662773 | D29: =IF(cfg_rd_mode="Single",(1+$AE$28)/(1+$AE$22)-1,(1+D28)/(1+D22)-1) -> 0.026363284 | E29: =IF(cfg_rd_mode="Single",(1+$AE$28)/(1+$AE$22)-1,(1+E28)/(1+E22)-1) -> 0.027994159 | F29: =IF(cfg_rd_mode="Single",(1+$AE$28)/(1+$AE$22)-1,(1+F28)/(1+F22)-1) -> 0.028880229 | G29: =IF(cfg_rd_mode="Single",(1+$AE$28)/(1+$AE$22)-1,(1+G28)/(1+G22)-1) -> 0.029268988 | H29: =IF(cfg_rd_mode="Single",(1+$AE$28)/(1+$AE$22)-1,(1+H28)/(1+H22)-1) -> 0.029329214 | I29: =IF(cfg_rd_mode="Single",(1+$AE$28)/(1+$AE$22)-1,(1+I28)/(1+I22)-1) -> 0.029169387 | ... AE29: =IF(cfg_rd_mode="Single",(1+$AE$28)/(1+$AE$22)-1,(1+AE28)/(1+AE22)-1) -> 0.045454086
A30: memo: implied credit spread (nom spot) | B30: =B27-(B23+B21) -> 0.009755 | C30: =C27-(C23+C21) -> 0.00906 | D30: =D27-(D23+D21) -> 0.008399 | E30: =E27-(E23+E21) -> 0.007771 | F30: =F27-(F23+F21) -> 0.007172 | G30: =G27-(G23+G21) -> 0.006604 | H30: =H27-(H23+H21) -> 0.006065 | I30: =I27-(I23+I21) -> 0.005553 | ... AE30: =AE27-(AE23+AE21) -> 0.013359

Sheet Cap Engine
A1: CAP ENGINE — economic restatement (PP&E vintage · R&D capitalization)
A2: PP&E vintages deflated on the BEA nonresidential fixed-investment index (capital-goods prices), gated by age<L, straight-line composite. L=in_ppe_life, anchor=in_anchor_year.
A4: PP&E VINTAGE RESTATEMENT
A6: Vintage yr | B6: Nominal capex | C6: Deflator(BEA)→2026$ | D6: Real capex 2026$ | E6: Age = A−v | F6: Live (age<L) | G6: Remaining (L−age)/L | H6: Real gross contrib | I6: Real net = real×rem | J6: v (num)
A7: 1989 | B7: =-INDEX(rep_capex,MATCH(A7,rep_years_cf,0)) -> 0.000239 | C7: =INDEX(md_deflator_ppe,MATCH(A7,md_years_bea,0)) -> 1.3124889 | D7: =B7*C7 -> 0.00031368484 | E7: =in_anchor_year-A7 -> 36 | F7: =IF(E7<in_ppe_life,1,0) -> 0 | G7: =MAX(0,(in_ppe_life-E7)/in_ppe_life) -> 0 | H7: =D7*F7 -> 0 | I7: =D7*G7 -> 0 | J7: =VALUE(A7) -> 1989
A8: 1990 | B8: =-INDEX(rep_capex,MATCH(A8,rep_years_cf,0)) -> 0.000224 | C8: =INDEX(md_deflator_ppe,MATCH(A8,md_years_bea,0)) -> 1.284901 | D8: =B8*C8 -> 0.00028781782 | E8: =in_anchor_year-A8 -> 35 | F8: =IF(E8<in_ppe_life,1,0) -> 0 | G8: =MAX(0,(in_ppe_life-E8)/in_ppe_life) -> 0 | H8: =D8*F8 -> 0 | I8: =D8*G8 -> 0 | J8: =VALUE(A8) -> 1990
A9: 1991 | B9: =-INDEX(rep_capex,MATCH(A9,rep_years_cf,0)) -> 0.000218 | C9: =INDEX(md_deflator_ppe,MATCH(A9,md_years_bea,0)) -> 1.2610303 | D9: =B9*C9 -> 0.0002749046 | E9: =in_anchor_year-A9 -> 34 | F9: =IF(E9<in_ppe_life,1,0) -> 0 | G9: =MAX(0,(in_ppe_life-E9)/in_ppe_life) -> 0 | H9: =D9*F9 -> 0 | I9: =D9*G9 -> 0 | J9: =VALUE(A9) -> 1991
A10: 1992 | B10: =-INDEX(rep_capex,MATCH(A10,rep_years_cf,0)) -> 0.000195 | C10: =INDEX(md_deflator_ppe,MATCH(A10,md_years_bea,0)) -> 1.2651661 | D10: =B10*C10 -> 0.0002467074 | E10: =in_anchor_year-A10 -> 33 | F10: =IF(E10<in_ppe_life,1,0) -> 0 | G10: =MAX(0,(in_ppe_life-E10)/in_ppe_life) -> 0 | H10: =D10*F10 -> 0 | I10: =D10*G10 -> 0 | J10: =VALUE(A10) -> 1992
A11: 1993 | B11: =-INDEX(rep_capex,MATCH(A11,rep_years_cf,0)) -> 0.000213 | C11: =INDEX(md_deflator_ppe,MATCH(A11,md_years_bea,0)) -> 1.2624464 | D11: =B11*C11 -> 0.00026890108 | E11: =in_anchor_year-A11 -> 32 | F11: =IF(E11<in_ppe_life,1,0) -> 0 | G11: =MAX(0,(in_ppe_life-E11)/in_ppe_life) -> 0 | H11: =D11*F11 -> 0 | I11: =D11*G11 -> 0 | J11: =VALUE(A11) -> 1993
A12: 1994 | B12: =-INDEX(rep_capex,MATCH(A12,rep_years_cf,0)) -> 0.00016 | C12: =INDEX(md_deflator_ppe,MATCH(A12,md_years_bea,0)) -> 1.2525733 | D12: =B12*C12 -> 0.00020041172 | E12: =in_anchor_year-A12 -> 31 | F12: =IF(E12<in_ppe_life,1,0) -> 0 | G12: =MAX(0,(in_ppe_life-E12)/in_ppe_life) -> 0 | H12: =D12*F12 -> 0 | I12: =D12*G12 -> 0 | J12: =VALUE(A12) -> 1994
A13: 1995 | B13: =-INDEX(rep_capex,MATCH(A13,rep_years_cf,0)) -> 0.000159 | C13: =INDEX(md_deflator_ppe,MATCH(A13,md_years_bea,0)) -> 1.2402156 | D13: =B13*C13 -> 0.00019719428 | E13: =in_anchor_year-A13 -> 30 | F13: =IF(E13<in_ppe_life,1,0) -> 0 | G13: =MAX(0,(in_ppe_life-E13)/in_ppe_life) -> 0 | H13: =D13*F13 -> 0 | I13: =D13*G13 -> 0 | J13: =VALUE(A13) -> 1995
A14: 1996 | B14: =-INDEX(rep_capex,MATCH(A14,rep_years_cf,0)) -> 6.7e-05 | C14: =INDEX(md_deflator_ppe,MATCH(A14,md_years_bea,0)) -> 1.2477933 | D14: =B14*C14 -> 8.3602152e-05 | E14: =in_anchor_year-A14 -> 29 | F14: =IF(E14<in_ppe_life,1,0) -> 0 | G14: =MAX(0,(in_ppe_life-E14)/in_ppe_life) -> 0 | H14: =D14*F14 -> 0 | I14: =D14*G14 -> 0 | J14: =VALUE(A14) -> 1996
A15: 1997 | B15: =-INDEX(rep_capex,MATCH(A15,rep_years_cf,0)) -> 5.3e-05 | C15: =INDEX(md_deflator_ppe,MATCH(A15,md_years_bea,0)) -> 1.2548102 | D15: =B15*C15 -> 6.6504943e-05 | E15: =in_anchor_year-A15 -> 28 | F15: =IF(E15<in_ppe_life,1,0) -> 0 | G15: =MAX(0,(in_ppe_life-E15)/in_ppe_life) -> 0 | H15: =D15*F15 -> 0 | I15: =D15*G15 -> 0 | J15: =VALUE(A15) -> 1997
A16: 1998 | B16: =-INDEX(rep_capex,MATCH(A16,rep_years_cf,0)) -> 5.6e-05 | C16: =INDEX(md_deflator_ppe,MATCH(A16,md_years_bea,0)) -> 1.2748126 | D16: =B16*C16 -> 7.1389507e-05 | E16: =in_anchor_year-A16 -> 27 | F16: =IF(E16<in_ppe_life,1,0) -> 0 | G16: =MAX(0,(in_ppe_life-E16)/in_ppe_life) -> 0 | H16: =D16*F16 -> 0 | I16: =D16*G16 -> 0 | J16: =VALUE(A16) -> 1998
A17: 1999 | B17: =-INDEX(rep_capex,MATCH(A17,rep_years_cf,0)) -> 4.7e-05 | C17: =INDEX(md_deflator_ppe,MATCH(A17,md_years_bea,0)) -> 1.2877185 | D17: =B17*C17 -> 6.0522767e-05 | E17: =in_anchor_year-A17 -> 26 | F17: =IF(E17<in_ppe_life,1,0) -> 0 | G17: =MAX(0,(in_ppe_life-E17)/in_ppe_life) -> 0 | H17: =D17*F17 -> 0 | I17: =D17*G17 -> 0 | J17: =VALUE(A17) -> 1999
A18: 2000 | B18: =-INDEX(rep_capex,MATCH(A18,rep_years_cf,0)) -> 0.000107 | C18: =INDEX(md_deflator_ppe,MATCH(A18,md_years_bea,0)) -> 1.2821098 | D18: =B18*C18 -> 0.00013718575 | E18: =in_anchor_year-A18 -> 25 | F18: =IF(E18<in_ppe_life,1,0) -> 0 | G18: =MAX(0,(in_ppe_life-E18)/in_ppe_life) -> 0 | H18: =D18*F18 -> 0 | I18: =D18*G18 -> 0 | J18: =VALUE(A18) -> 2000
... A43: 2025 | B43: =-INDEX(rep_capex,MATCH(A43,rep_years_cf,0)) -> 0.012715 | C43: =INDEX(md_deflator_ppe,MATCH(A43,md_years_bea,0)) -> 1.0172442 | D43: =B43*C43 -> 0.01293426 | E43: =in_anchor_year-A43 -> 0 | F43: =IF(E43<in_ppe_life,1,0) -> 1 | G43: =MAX(0,(in_ppe_life-E43)/in_ppe_life) -> 1 | H43: =D43*F43 -> 0.01293426 | I43: =D43*G43 -> 0.01293426 | J43: =VALUE(A43) -> 2025
A45: REAL PP&E ANCHOR (FY = in_anchor_year, real 2026$)
A46: Real gross PP&E = Σ gross contrib | B46: =SUM(H7:H43) -> 0.13778217
A47: Real net PP&E = Σ real net | B47: =SUM(I7:I43) -> 0.067457873
A48: Real accum. deprec. = gross − net | B48: =B46-B47 -> 0.070324299
A49: Economic depreciation = real gross / L | B49: =B46/in_ppe_life -> 0.013286613
A51: RECONCILIATION vs reported nominal PP&E
A52: Reported nominal gross PP&E | B52: =INDEX(rep_gross_ppe,MATCH(in_anchor_year&"",rep_years_bs,0)) -> 0.125848
A53: Reported nominal net PP&E | B53: =INDEX(rep_net_ppe,MATCH(in_anchor_year&"",rep_years_bs,0)) -> 0.049834
A54: Real/nominal gross ratio | B54: =B46/B52 -> 1.0948301
A55: Real/nominal net ratio | B55: =B47/B53 -> 1.3536516
A56: Live-vintage count | B56: =SUM(F7:F43) -> 11
A58: R&D CAPITALIZATION (general)
A59: R&D expense reported ($mm) [Inputs] | B59: =in_rd_expense0 -> 0
A60: R&D amortization life (Inputs) | B60: =in_rd_life -> 5
A61: R&D reserve = expense × life | B61: =B59*B60 -> 0
A64: PER-YEAR ECONOMIC PP&E SERIES (real 2026$; each year re-ages live vintages)
A65: Anchor year t | B65: =C65-1 -> 2008 | C65: =D65-1 -> 2009 | D65: =E65-1 -> 2010 | E65: =F65-1 -> 2011 | F65: =G65-1 -> 2012 | G65: =H65-1 -> 2013 | H65: =I65-1 -> 2014 | I65: =J65-1 -> 2015 | ... R65: =S65-1 -> 2024 | S65: =in_anchor_year -> 2025
A66: Real gross PP&E(t) | B66: =SUMPRODUCT($D$7:$D$43*($J$7:$J$43<=B65)*((B65-$J$7:$J$43)<in_ppe_life)) -> 0.0045564179 | C66: =SUMPRODUCT($D$7:$D$43*($J$7:$J$43<=C65)*((C65-$J$7:$J$43)<in_ppe_life)) -> 0.0058561371 | D66: =SUMPRODUCT($D$7:$D$43*($J$7:$J$43<=D65)*((D65-$J$7:$J$43)<in_ppe_life)) -> 0.0082432094 | E66: =SUMPRODUCT($D$7:$D$43*($J$7:$J$43<=E65)*((E65-$J$7:$J$43)<in_ppe_life)) -> 0.013249958 | F66: =SUMPRODUCT($D$7:$D$43*($J$7:$J$43<=F65)*((F65-$J$7:$J$43)<in_ppe_life)) -> 0.022828662 | G66: =SUMPRODUCT($D$7:$D$43*($J$7:$J$43<=G65)*((G65-$J$7:$J$43)<in_ppe_life)) -> 0.032316353 | H66: =SUMPRODUCT($D$7:$D$43*($J$7:$J$43<=H65)*((H65-$J$7:$J$43)<in_ppe_life)) -> 0.043381032 | I66: =SUMPRODUCT($D$7:$D$43*($J$7:$J$43<=I65)*((I65-$J$7:$J$43)<in_ppe_life)) -> 0.056384073 | ... S66: =SUMPRODUCT($D$7:$D$43*($J$7:$J$43<=S65)*((S65-$J$7:$J$43)<in_ppe_life)) -> 0.13778217
A67: Real net PP&E(t) | B67: =SUMPRODUCT($D$7:$D$43*($J$7:$J$43<=B65)*((in_ppe_life-(B65-$J$7:$J$43))>0)*(in_ppe_life-(B65-$J$7:$J$43))/in_ppe_life) -> 0.0034704881 | C67: =SUMPRODUCT($D$7:$D$43*($J$7:$J$43<=C65)*((in_ppe_life-(C65-$J$7:$J$43))>0)*(in_ppe_life-(C65-$J$7:$J$43))/in_ppe_life) -> 0.0044065493 | D67: =SUMPRODUCT($D$7:$D$43*($J$7:$J$43<=D65)*((in_ppe_life-(D65-$J$7:$J$43))>0)*(in_ppe_life-(D65-$J$7:$J$43))/in_ppe_life) -> 0.0062931021 | E67: =SUMPRODUCT($D$7:$D$43*($J$7:$J$43<=E65)*((in_ppe_life-(E65-$J$7:$J$43))>0)*(in_ppe_life-(E65-$J$7:$J$43))/in_ppe_life) -> 0.010650461 | F67: =SUMPRODUCT($D$7:$D$43*($J$7:$J$43<=F65)*((in_ppe_life-(F65-$J$7:$J$43))>0)*(in_ppe_life-(F65-$J$7:$J$43))/in_ppe_life) -> 0.019268235 | G67: =SUMPRODUCT($D$7:$D$43*($J$7:$J$43<=G65)*((in_ppe_life-(G65-$J$7:$J$43))>0)*(in_ppe_life-(G65-$J$7:$J$43))/in_ppe_life) -> 0.026793353 | H67: =SUMPRODUCT($D$7:$D$43*($J$7:$J$43<=H65)*((in_ppe_life-(H65-$J$7:$J$43))>0)*(in_ppe_life-(H65-$J$7:$J$43))/in_ppe_life) -> 0.034968562 | I67: =SUMPRODUCT($D$7:$D$43*($J$7:$J$43<=I65)*((in_ppe_life-(I65-$J$7:$J$43))>0)*(in_ppe_life-(I65-$J$7:$J$43))/in_ppe_life) -> 0.044029363 | ... S67: =SUMPRODUCT($D$7:$D$43*($J$7:$J$43<=S65)*((in_ppe_life-(S65-$J$7:$J$43))>0)*(in_ppe_life-(S65-$J$7:$J$43))/in_ppe_life) -> 0.067457873
A68: Economic depreciation(t) | B68: =B66/in_ppe_life -> 0.00043938456 | C68: =C66/in_ppe_life -> 0.00056471911 | D68: =D66/in_ppe_life -> 0.0007949093 | E68: =E66/in_ppe_life -> 0.0012777201 | F68: =F66/in_ppe_life -> 0.0022014139 | G68: =G66/in_ppe_life -> 0.0031163311 | H68: =H66/in_ppe_life -> 0.0041833203 | I68: =I66/in_ppe_life -> 0.0054372298 | ... S68: =S66/in_ppe_life -> 0.013286613

Sheet Econ Statements
A1: ECON STATEMENTS — reformulated IS/BS (real 2026$) [historical restatement stays REAL 2026$ — presentation basis]
A2: General: pulls reported rows by named range + INDEX/MATCH, Cap Engine real PP&E, Market Data deflators, Inputs assumptions. Partition: MI+pension in NFO. PP&E on BEA; other items on CPI. Effective-rate tax.
A4: Restatement view (cfg_restatement): | B4: =cfg_restatement -> Economic
A5: Fiscal year | B5: =TEXT(VALUE(C$5)-1,"0") -> 2008 | C5: =TEXT(VALUE(D$5)-1,"0") -> 2009 | D5: =TEXT(VALUE(E$5)-1,"0") -> 2010 | E5: =TEXT(VALUE(F$5)-1,"0") -> 2011 | F5: =TEXT(VALUE(G$5)-1,"0") -> 2012 | G5: =TEXT(VALUE(H$5)-1,"0") -> 2013 | H5: =TEXT(VALUE(I$5)-1,"0") -> 2014 | I5: =TEXT(VALUE(J$5)-1,"0") -> 2015 | ... R5: =TEXT(VALUE(S$5)-1,"0") -> 2024 | S5: =TEXT(in_anchor_year,"0") -> 2025
A6: CPI deflator [MULTIPLIER: nominal x this = base-year 2026$. Do NOT divide.] | B6: =IFERROR(INDEX(md_deflator,MATCH(B$5,md_years,0)),1) -> 1.556518 | C6: =IFERROR(INDEX(md_deflator,MATCH(C$5,md_years,0)),1) -> 1.5620755 | D6: =IFERROR(INDEX(md_deflator,MATCH(D$5,md_years,0)),1) -> 1.5368667 | E6: =IFERROR(INDEX(md_deflator,MATCH(E$5,md_years,0)),1) -> 1.4898395 | F6: =IFERROR(INDEX(md_deflator,MATCH(F$5,md_years,0)),1) -> 1.4596331 | G6: =IFERROR(INDEX(md_deflator,MATCH(G$5,md_years,0)),1) -> 1.4385616 | H6: =IFERROR(INDEX(md_deflator,MATCH(H$5,md_years,0)),1) -> 1.415598 | I6: =IFERROR(INDEX(md_deflator,MATCH(I$5,md_years,0)),1) -> 1.4139197 | ... S6: =IFERROR(INDEX(md_deflator,MATCH(S$5,md_years,0)),1) -> 1.0409389
A7: BEA deflator [MULTIPLIER: nominal x this = base-year 2026$. Do NOT divide.] | B7: =IFERROR(INDEX(md_deflator_ppe,MATCH(B$5,md_years_bea,0)),1) -> 1.1907356 | C7: =IFERROR(INDEX(md_deflator_ppe,MATCH(C$5,md_years_bea,0)),1) -> 1.1985216 | D7: =IFERROR(INDEX(md_deflator_ppe,MATCH(D$5,md_years_bea,0)),1) -> 1.2207456 | E7: =IFERROR(INDEX(md_deflator_ppe,MATCH(E$5,md_years_bea,0)),1) -> 1.2074962 | F7: =IFERROR(INDEX(md_deflator_ppe,MATCH(F$5,md_years_bea,0)),1) -> 1.1907596 | G7: =IFERROR(INDEX(md_deflator_ppe,MATCH(G$5,md_years_bea,0)),1) -> 1.1895716 | H7: =IFERROR(INDEX(md_deflator_ppe,MATCH(H$5,md_years_bea,0)),1) -> 1.1784085 | I7: =IFERROR(INDEX(md_deflator_ppe,MATCH(I$5,md_years_bea,0)),1) -> 1.1763416 | ... S7: =IFERROR(INDEX(md_deflator_ppe,MATCH(S$5,md_years_bea,0)),1) -> 1.0172442
A9: REPORTED (nominal $mm)
A10: Total assets | B10: =IFERROR(INDEX(rep_total_assets,MATCH(B$5,rep_years_bs,0)),0) -> 0.039572 | C10: =IFERROR(INDEX(rep_total_assets,MATCH(C$5,rep_years_bs,0)),0) -> 0.053851 | D10: =IFERROR(INDEX(rep_total_assets,MATCH(D$5,rep_years_bs,0)),0) -> 0.075183 | E10: =IFERROR(INDEX(rep_total_assets,MATCH(E$5,rep_years_bs,0)),0) -> 0.116371 | F10: =IFERROR(INDEX(rep_total_assets,MATCH(F$5,rep_years_bs,0)),0) -> 0.176064 | G10: =IFERROR(INDEX(rep_total_assets,MATCH(G$5,rep_years_bs,0)),0) -> 0.207 | H10: =IFERROR(INDEX(rep_total_assets,MATCH(H$5,rep_years_bs,0)),0) -> 0.231839 | I10: =IFERROR(INDEX(rep_total_assets,MATCH(I$5,rep_years_bs,0)),0) -> 0.290479 | ... S10: =IFERROR(INDEX(rep_total_assets,MATCH(S$5,rep_years_bs,0)),0) -> 0.359241
A11: Total liabilities | B11: =IFERROR(INDEX(rep_total_liab,MATCH(B$5,rep_years_bs,0)),0) -> 0.018542 | C11: =IFERROR(INDEX(rep_total_liab,MATCH(C$5,rep_years_bs,0)),0) -> 0.026019 | D11: =IFERROR(INDEX(rep_total_liab,MATCH(D$5,rep_years_bs,0)),0) -> 0.027392 | E11: =IFERROR(INDEX(rep_total_liab,MATCH(E$5,rep_years_bs,0)),0) -> 0.039756 | F11: =IFERROR(INDEX(rep_total_liab,MATCH(F$5,rep_years_bs,0)),0) -> 0.057854 | G11: =IFERROR(INDEX(rep_total_liab,MATCH(G$5,rep_years_bs,0)),0) -> 0.083451 | H11: =IFERROR(INDEX(rep_total_liab,MATCH(H$5,rep_years_bs,0)),0) -> 0.120292 | I11: =IFERROR(INDEX(rep_total_liab,MATCH(I$5,rep_years_bs,0)),0) -> 0.171124 | ... S11: =IFERROR(INDEX(rep_total_liab,MATCH(S$5,rep_years_bs,0)),0) -> 0.285508
A12: Cash | B12: =IFERROR(INDEX(rep_cash,MATCH(B$5,rep_years_bs,0)),0) -> 0.011875 | C12: =IFERROR(INDEX(rep_cash,MATCH(C$5,rep_years_bs,0)),0) -> 0.005263 | D12: =IFERROR(INDEX(rep_cash,MATCH(D$5,rep_years_bs,0)),0) -> 0.011261 | E12: =IFERROR(INDEX(rep_cash,MATCH(E$5,rep_years_bs,0)),0) -> 0.009815 | F12: =IFERROR(INDEX(rep_cash,MATCH(F$5,rep_years_bs,0)),0) -> 0.010746 | G12: =IFERROR(INDEX(rep_cash,MATCH(G$5,rep_years_bs,0)),0) -> 0.014259 | H12: =IFERROR(INDEX(rep_cash,MATCH(H$5,rep_years_bs,0)),0) -> 0.013844 | I12: =IFERROR(INDEX(rep_cash,MATCH(I$5,rep_years_bs,0)),0) -> 0.02112 | ... S12: =IFERROR(INDEX(rep_cash,MATCH(S$5,rep_years_bs,0)),0) -> 0.035934
A13: Short-term investments | B13: =IFERROR(INDEX(rep_sti,MATCH(B$5,rep_years_bs,0)),0) -> 0.012615 | C13: =IFERROR(INDEX(rep_sti,MATCH(C$5,rep_years_bs,0)),0) -> 0.018201 | D13: =IFERROR(INDEX(rep_sti,MATCH(D$5,rep_years_bs,0)),0) -> 0.014359 | E13: =IFERROR(INDEX(rep_sti,MATCH(E$5,rep_years_bs,0)),0) -> 0.016137 | F13: =IFERROR(INDEX(rep_sti,MATCH(F$5,rep_years_bs,0)),0) -> 0.018383 | G13: =IFERROR(INDEX(rep_sti,MATCH(G$5,rep_years_bs,0)),0) -> 0.026287 | H13: =IFERROR(INDEX(rep_sti,MATCH(H$5,rep_years_bs,0)),0) -> 0.011233 | I13: =IFERROR(INDEX(rep_sti,MATCH(I$5,rep_years_bs,0)),0) -> 0.020481 | ... S13: =IFERROR(INDEX(rep_sti,MATCH(S$5,rep_years_bs,0)),0) -> 0.018763
A14: Total debt | B14: =IFERROR(INDEX(rep_total_debt,MATCH(B$5,rep_years_bs,0)),0) -> 0 | C14: =IFERROR(INDEX(rep_total_debt,MATCH(C$5,rep_years_bs,0)),0) -> 0 | D14: =IFERROR(INDEX(rep_total_debt,MATCH(D$5,rep_years_bs,0)),0) -> 0 | E14: =IFERROR(INDEX(rep_total_debt,MATCH(E$5,rep_years_bs,0)),0) -> 0 | F14: =IFERROR(INDEX(rep_total_debt,MATCH(F$5,rep_years_bs,0)),0) -> 0 | G14: =IFERROR(INDEX(rep_total_debt,MATCH(G$5,rep_years_bs,0)),0) -> 0.01696 | H14: =IFERROR(INDEX(rep_total_debt,MATCH(H$5,rep_years_bs,0)),0) -> 0.035295 | I14: =IFERROR(INDEX(rep_total_debt,MATCH(I$5,rep_years_bs,0)),0) -> 0.064462 | ... S14: =IFERROR(INDEX(rep_total_debt,MATCH(S$5,rep_years_bs,0)),0) -> 0.112377
A15: Pension (NC) | B15: =IFERROR(INDEX(rep_pension,MATCH(B$5,rep_years_bs,0)),0) -> 0 | C15: =IFERROR(INDEX(rep_pension,MATCH(C$5,rep_years_bs,0)),0) -> 0 | D15: =IFERROR(INDEX(rep_pension,MATCH(D$5,rep_years_bs,0)),0) -> 0 | E15: =IFERROR(INDEX(rep_pension,MATCH(E$5,rep_years_bs,0)),0) -> 0 | F15: =IFERROR(INDEX(rep_pension,MATCH(F$5,rep_years_bs,0)),0) -> 0 | G15: =IFERROR(INDEX(rep_pension,MATCH(G$5,rep_years_bs,0)),0) -> 0 | H15: =IFERROR(INDEX(rep_pension,MATCH(H$5,rep_years_bs,0)),0) -> 0 | I15: =IFERROR(INDEX(rep_pension,MATCH(I$5,rep_years_bs,0)),0) -> 0 | ... S15: =IFERROR(INDEX(rep_pension,MATCH(S$5,rep_years_bs,0)),0) -> 0
A16: Minority interest | B16: =IFERROR(INDEX(rep_mi,MATCH(B$5,rep_years_bs,0)),0) -> 0 | C16: =IFERROR(INDEX(rep_mi,MATCH(C$5,rep_years_bs,0)),0) -> 0 | D16: =IFERROR(INDEX(rep_mi,MATCH(D$5,rep_years_bs,0)),0) -> 0 | E16: =IFERROR(INDEX(rep_mi,MATCH(E$5,rep_years_bs,0)),0) -> 0 | F16: =IFERROR(INDEX(rep_mi,MATCH(F$5,rep_years_bs,0)),0) -> 0 | G16: =IFERROR(INDEX(rep_mi,MATCH(G$5,rep_years_bs,0)),0) -> 0 | H16: =IFERROR(INDEX(rep_mi,MATCH(H$5,rep_years_bs,0)),0) -> 0 | I16: =IFERROR(INDEX(rep_mi,MATCH(I$5,rep_years_bs,0)),0) -> 0 | ... S16: =IFERROR(INDEX(rep_mi,MATCH(S$5,rep_years_bs,0)),0) -> 0
A17: Reported net PP&E | B17: =IFERROR(INDEX(rep_net_ppe,MATCH(B$5,rep_years_bs,0)),0) -> 0.002455 | C17: =IFERROR(INDEX(rep_net_ppe,MATCH(C$5,rep_years_bs,0)),0) -> 0.002954 | D17: =IFERROR(INDEX(rep_net_ppe,MATCH(D$5,rep_years_bs,0)),0) -> 0.004768 | E17: =IFERROR(INDEX(rep_net_ppe,MATCH(E$5,rep_years_bs,0)),0) -> 0.007777 | F17: =IFERROR(INDEX(rep_net_ppe,MATCH(F$5,rep_years_bs,0)),0) -> 0.015452 | G17: =IFERROR(INDEX(rep_net_ppe,MATCH(G$5,rep_years_bs,0)),0) -> 0.016597 | H17: =IFERROR(INDEX(rep_net_ppe,MATCH(H$5,rep_years_bs,0)),0) -> 0.020624 | I17: =IFERROR(INDEX(rep_net_ppe,MATCH(I$5,rep_years_bs,0)),0) -> 0.022471 | ... S17: =IFERROR(INDEX(rep_net_ppe,MATCH(S$5,rep_years_bs,0)),0) -> 0.049834
A18: Reported CSE (common) | B18: =IFERROR(INDEX(rep_cse,MATCH(B$5,rep_years_bs,0)),0) -> 0.02103 | C18: =IFERROR(INDEX(rep_cse,MATCH(C$5,rep_years_bs,0)),0) -> 0.027832 | D18: =IFERROR(INDEX(rep_cse,MATCH(D$5,rep_years_bs,0)),0) -> 0.047791 | E18: =IFERROR(INDEX(rep_cse,MATCH(E$5,rep_years_bs,0)),0) -> 0.076615 | F18: =IFERROR(INDEX(rep_cse,MATCH(F$5,rep_years_bs,0)),0) -> 0.11821 | G18: =IFERROR(INDEX(rep_cse,MATCH(G$5,rep_years_bs,0)),0) -> 0.123549 | H18: =IFERROR(INDEX(rep_cse,MATCH(H$5,rep_years_bs,0)),0) -> 0.111547 | I18: =IFERROR(INDEX(rep_cse,MATCH(I$5,rep_years_bs,0)),0) -> 0.119355 | ... S18: =IFERROR(INDEX(rep_cse,MATCH(S$5,rep_years_bs,0)),0) -> 0.073733
A19: Shares (mm) | B19: =IFERROR(INDEX(rep_shares,MATCH(B$5,rep_years_bs,0)),0) -> 0.02526 | C19: =IFERROR(INDEX(rep_shares,MATCH(C$5,rep_years_bs,0)),0) -> 0.025396 | D19: =IFERROR(INDEX(rep_shares,MATCH(D$5,rep_years_bs,0)),0) -> 0.025892 | E19: =IFERROR(INDEX(rep_shares,MATCH(E$5,rep_years_bs,0)),0) -> 0.026226 | F19: =IFERROR(INDEX(rep_shares,MATCH(F$5,rep_years_bs,0)),0) -> 0.02647 | G19: =IFERROR(INDEX(rep_shares,MATCH(G$5,rep_years_bs,0)),0) -> 0.026087 | H19: =IFERROR(INDEX(rep_shares,MATCH(H$5,rep_years_bs,0)),0) -> 0.024491 | I19: =IFERROR(INDEX(rep_shares,MATCH(I$5,rep_years_bs,0)),0) -> 0.023172 | ... S19: =IFERROR(INDEX(rep_shares,MATCH(S$5,rep_years_bs,0)),0) -> 0.015005
A20: Operating income | B20: =IFERROR(INDEX(rep_oi,MATCH(B$5,rep_years_is,0)),0) -> 0.006275 | C20: =IFERROR(INDEX(rep_oi,MATCH(C$5,rep_years_is,0)),0) -> 0.01137 | D20: =IFERROR(INDEX(rep_oi,MATCH(D$5,rep_years_is,0)),0) -> 0.018385 | E20: =IFERROR(INDEX(rep_oi,MATCH(E$5,rep_years_is,0)),0) -> 0.03379 | F20: =IFERROR(INDEX(rep_oi,MATCH(F$5,rep_years_is,0)),0) -> 0.055241 | G20: =IFERROR(INDEX(rep_oi,MATCH(G$5,rep_years_is,0)),0) -> 0.048999 | H20: =IFERROR(INDEX(rep_oi,MATCH(H$5,rep_years_is,0)),0) -> 0.052503 | I20: =IFERROR(INDEX(rep_oi,MATCH(I$5,rep_years_is,0)),0) -> 0.07123 | ... S20: =IFERROR(INDEX(rep_oi,MATCH(S$5,rep_years_is,0)),0) -> 0.13305
A21: D&A (reconciled) | B21: =IFERROR(INDEX(rep_da,MATCH(B$5,rep_years_is,0)),0) -> 0 | C21: =IFERROR(INDEX(rep_da,MATCH(C$5,rep_years_is,0)),0) -> 0 | D21: =IFERROR(INDEX(rep_da,MATCH(D$5,rep_years_is,0)),0) -> 0 | E21: =IFERROR(INDEX(rep_da,MATCH(E$5,rep_years_is,0)),0) -> 0 | F21: =IFERROR(INDEX(rep_da,MATCH(F$5,rep_years_is,0)),0) -> 0 | G21: =IFERROR(INDEX(rep_da,MATCH(G$5,rep_years_is,0)),0) -> 0 | H21: =IFERROR(INDEX(rep_da,MATCH(H$5,rep_years_is,0)),0) -> 0 | I21: =IFERROR(INDEX(rep_da,MATCH(I$5,rep_years_is,0)),0) -> 0 | ... S21: =IFERROR(INDEX(rep_da,MATCH(S$5,rep_years_is,0)),0) -> 0.011698
A22: Net income (common) | B22: =IFERROR(INDEX(rep_ni,MATCH(B$5,rep_years_is,0)),0) -> 0.004834 | C22: =IFERROR(INDEX(rep_ni,MATCH(C$5,rep_years_is,0)),0) -> 0.008235 | D22: =IFERROR(INDEX(rep_ni,MATCH(D$5,rep_years_is,0)),0) -> 0.014013 | E22: =IFERROR(INDEX(rep_ni,MATCH(E$5,rep_years_is,0)),0) -> 0.025922 | F22: =IFERROR(INDEX(rep_ni,MATCH(F$5,rep_years_is,0)),0) -> 0.041733 | G22: =IFERROR(INDEX(rep_ni,MATCH(G$5,rep_years_is,0)),0) -> 0.037037 | H22: =IFERROR(INDEX(rep_ni,MATCH(H$5,rep_years_is,0)),0) -> 0.03951 | I22: =IFERROR(INDEX(rep_ni,MATCH(I$5,rep_years_is,0)),0) -> 0.053394 | ... S22: =IFERROR(INDEX(rep_ni,MATCH(S$5,rep_years_is,0)),0) -> 0.11201
A23: Interest expense | B23: =IFERROR(INDEX(rep_intexp,MATCH(B$5,rep_years_is,0)),0) -> 0.00062 | C23: =IFERROR(INDEX(rep_intexp,MATCH(C$5,rep_years_is,0)),0) -> 0.000326 | D23: =IFERROR(INDEX(rep_intexp,MATCH(D$5,rep_years_is,0)),0) -> 0.000155 | E23: =IFERROR(INDEX(rep_intexp,MATCH(E$5,rep_years_is,0)),0) -> 0.000415 | F23: =IFERROR(INDEX(rep_intexp,MATCH(F$5,rep_years_is,0)),0) -> 0.000522 | G23: =IFERROR(INDEX(rep_intexp,MATCH(G$5,rep_years_is,0)),0) -> 0.000136 | H23: =IFERROR(INDEX(rep_intexp,MATCH(H$5,rep_years_is,0)),0) -> 0.000384 | I23: =IFERROR(INDEX(rep_intexp,MATCH(I$5,rep_years_is,0)),0) -> 0.000733 | ... S23: =IFERROR(INDEX(rep_intexp,MATCH(S$5,rep_years_is,0)),0) -> 0
A24: Tax rate | B24: =IFERROR(INDEX(rep_taxrate,MATCH(B$5,rep_years_is,0)),0) -> 0.298912 | C24: =IFERROR(INDEX(rep_taxrate,MATCH(C$5,rep_years_is,0)),0) -> 0.317504 | D24: =IFERROR(INDEX(rep_taxrate,MATCH(D$5,rep_years_is,0)),0) -> 0.244175 | E24: =IFERROR(INDEX(rep_taxrate,MATCH(E$5,rep_years_is,0)),0) -> 0.242158 | F24: =IFERROR(INDEX(rep_taxrate,MATCH(F$5,rep_years_is,0)),0) -> 0.251601 | G24: =IFERROR(INDEX(rep_taxrate,MATCH(G$5,rep_years_is,0)),0) -> 0.261549 | H24: =IFERROR(INDEX(rep_taxrate,MATCH(H$5,rep_years_is,0)),0) -> 0.261261 | I24: =IFERROR(INDEX(rep_taxrate,MATCH(I$5,rep_years_is,0)),0) -> 0.263683 | ... S24: =IFERROR(INDEX(rep_taxrate,MATCH(S$5,rep_years_is,0)),0) -> 0.1561
A25: OCI | B25: =IFERROR(INDEX(rep_oci,MATCH(B$5,rep_years_bs,0)),0) -> 8e-06 | C25: =IFERROR(INDEX(rep_oci,MATCH(C$5,rep_years_bs,0)),0) -> 8.4e-05 | D25: =IFERROR(INDEX(rep_oci,MATCH(D$5,rep_years_bs,0)),0) -> -4.6e-05 | E25: =IFERROR(INDEX(rep_oci,MATCH(E$5,rep_years_bs,0)),0) -> 0.000443 | F25: =IFERROR(INDEX(rep_oci,MATCH(F$5,rep_years_bs,0)),0) -> 0.000499 | G25: =IFERROR(INDEX(rep_oci,MATCH(G$5,rep_years_bs,0)),0) -> -0.000471 | H25: =IFERROR(INDEX(rep_oci,MATCH(H$5,rep_years_bs,0)),0) -> 0.001082 | I25: =IFERROR(INDEX(rep_oci,MATCH(I$5,rep_years_bs,0)),0) -> -0.000345 | ... S25: =IFERROR(INDEX(rep_oci,MATCH(S$5,rep_years_bs,0)),0) -> -0.005571
A26: Dividends paid | B26: =IFERROR(INDEX(rep_div,MATCH(B$5,rep_years_cf,0)),0) -> 0 | C26: =IFERROR(INDEX(rep_div,MATCH(C$5,rep_years_cf,0)),0) -> 0 | D26: =IFERROR(INDEX(rep_div,MATCH(D$5,rep_years_cf,0)),0) -> 0 | E26: =IFERROR(INDEX(rep_div,MATCH(E$5,rep_years_cf,0)),0) -> 0 | F26: =IFERROR(INDEX(rep_div,MATCH(F$5,rep_years_cf,0)),0) -> -0.002488 | G26: =IFERROR(INDEX(rep_div,MATCH(G$5,rep_years_cf,0)),0) -> -0.010564 | H26: =IFERROR(INDEX(rep_div,MATCH(H$5,rep_years_cf,0)),0) -> -0.011126 | I26: =IFERROR(INDEX(rep_div,MATCH(I$5,rep_years_cf,0)),0) -> -0.011561 | ... S26: =IFERROR(INDEX(rep_div,MATCH(S$5,rep_years_cf,0)),0) -> -0.015421
A27: Repurchases | B27: =IFERROR(INDEX(rep_repurch,MATCH(B$5,rep_years_cf,0)),0) -> -0.000124 | C27: =IFERROR(INDEX(rep_repurch,MATCH(C$5,rep_years_cf,0)),0) -> -0.000475 | D27: =IFERROR(INDEX(rep_repurch,MATCH(D$5,rep_years_cf,0)),0) -> -0.000912 | E27: =IFERROR(INDEX(rep_repurch,MATCH(E$5,rep_years_cf,0)),0) -> -0.000831 | F27: =IFERROR(INDEX(rep_repurch,MATCH(F$5,rep_years_cf,0)),0) -> -0.000665 | G27: =IFERROR(INDEX(rep_repurch,MATCH(G$5,rep_years_cf,0)),0) -> -0.02286 | H27: =IFERROR(INDEX(rep_repurch,MATCH(H$5,rep_years_cf,0)),0) -> -0.045 | I27: =IFERROR(INDEX(rep_repurch,MATCH(I$5,rep_years_cf,0)),0) -> -0.035253 | ... S27: =IFERROR(INDEX(rep_repurch,MATCH(S$5,rep_years_cf,0)),0) -> -0.090711
A29: PARTITION (nominal)
A30: Financial obligations | B30: =B14+B15 -> 0 | C30: =C14+C15 -> 0 | D30: =D14+D15 -> 0 | E30: =E14+E15 -> 0 | F30: =F14+F15 -> 0 | G30: =G14+G15 -> 0.01696 | H30: =H14+H15 -> 0.035295 | I30: =I14+I15 -> 0.064462 | ... S30: =S14+S15 -> 0.112377
A31: Financial assets | B31: =B12+B13 -> 0.02449 | C31: =C12+C13 -> 0.023464 | D31: =D12+D13 -> 0.02562 | E31: =E12+E13 -> 0.025952 | F31: =F12+F13 -> 0.029129 | G31: =G12+G13 -> 0.040546 | H31: =H12+H13 -> 0.025077 | I31: =I12+I13 -> 0.041601 | ... S31: =S12+S13 -> 0.054697
A32: NFO (nominal) | B32: =B30-B31+B16 -> -0.02449 | C32: =C30-C31+C16 -> -0.023464 | D32: =D30-D31+D16 -> -0.02562 | E32: =E30-E31+E16 -> -0.025952 | F32: =F30-F31+F16 -> -0.029129 | G32: =G30-G31+G16 -> -0.023586 | H32: =H30-H31+H16 -> 0.010218 | I32: =I30-I31+I16 -> 0.022861 | ... S32: =S30-S31+S16 -> 0.05768
A33: Operating assets | B33: =B10-B31 -> 0.015082 | C33: =C10-C31 -> 0.030387 | D33: =D10-D31 -> 0.049563 | E33: =E10-E31 -> 0.090419 | F33: =F10-F31 -> 0.146935 | G33: =G10-G31 -> 0.166454 | H33: =H10-H31 -> 0.206762 | I33: =I10-I31 -> 0.248878 | ... S33: =S10-S31 -> 0.304544
A34: Operating liabilities | B34: =B11-B30 -> 0.018542 | C34: =C11-C30 -> 0.026019 | D34: =D11-D30 -> 0.027392 | E34: =E11-E30 -> 0.039756 | F34: =F11-F30 -> 0.057854 | G34: =G11-G30 -> 0.066491 | H34: =H11-H30 -> 0.084997 | I34: =I11-I30 -> 0.106662 | ... S34: =S11-S30 -> 0.173131
A35: NOA (nominal, reported PP&E) | B35: =B33-B34 -> -0.00346 | C35: =C33-C34 -> 0.004368 | D35: =D33-D34 -> 0.022171 | E35: =E33-E34 -> 0.050663 | F35: =F33-F34 -> 0.089081 | G35: =G33-G34 -> 0.099963 | H35: =H33-H34 -> 0.121765 | I35: =I33-I34 -> 0.142216 | ... S35: =S33-S34 -> 0.131413
A36: CSE (reported) | B36: =B18 -> 0.02103 | C36: =C18 -> 0.027832 | D36: =D18 -> 0.047791 | E36: =E18 -> 0.076615 | F36: =F18 -> 0.11821 | G36: =G18 -> 0.123549 | H36: =H18 -> 0.111547 | I36: =I18 -> 0.119355 | ... S36: =S18 -> 0.073733
A37: tie: NOA−NFO−CSE (nom) | B37: =B35-B32-B18 -> 0 | C37: =C35-C32-C18 -> 0 | D37: =D35-D32-D18 -> 0 | E37: =E35-E32-E18 -> 0 | F37: =F35-F32-F18 -> 0 | G37: =G35-G32-G18 -> 0 | H37: =H35-H32-H18 -> 0 | I37: =I35-I32-I18 -> 0 | ... S37: =S35-S32-S18 -> 0
A39: ECONOMIC RESTATEMENT (real 2026$)
